Workbook

Sheet OLD
A1: Notes: This is a copy of the "best guess" CEA of GFI created by Giving Green focused on the impact of GFI securing public fundng for alt protein R&D. This CEA only focuses on meat producing land animals as the original analysis that Giving Green's CEA was based on only considered "livestock". Note that this has a global focus. The only differences I have made are: 1. I have used a 1.4% discount for future benefits. 2. I model animal welfare impacts in addition to the climate impacts that were already modelled by Giving Green.
B2: Parameter | C2: Notes | D2: Source
A3: Cost
A4: GFI's budget, 2016-2022 | B4: =sum('GFIs spending'!B5:B11) -> 101130900 | C4: Total spending over 2016-2022 period | D4: Giving Green CEA
A6: Discounts
A7: Change in probability of moving from low- to high-innovation scenario due to securing public funding for AP R&D | B7: =AVERAGE(5%,20%) -> 0.125 | C7: Guess - 5-20%
A8: Percent impact that GFI has on securing public funding for AP R&D | B8: =AVERAGE(0.5%,2.5%) -> 0.015 | C8: Guess - 0.5-2.5%
A9: Change in probability of moving to the high-innovation scenario due to GFI | B9: =B7*B8 -> 0.001875 | C9: Calculation
A10: Effectiveness adjustment for marginal donation going to international efforts instead of US-based R&D | B10: 1 | C10: Guess
A12: Impacts | B12: Best guess
A13: # of years before the high-innovation scenario is roughly similar to BAU in the absence of GFI | B13: 15 | C13: Guess | D13: Giving Green CEA
A14: The difference in livestock production between adjusted high- and adjusted low-innovation scenarios over years of interest (million tons per year) | B14: {=NPV(0.014,'Livestock production'!F8:F21)} -> 378.35482 | C14: Calculation | D14: Giving Green CEA
A16: Animal impacts
A17: Number of animals
A18: % of livestock production made up by beef cows | B18: ='Land animal numbers'!L201 -> #REF! | C18: Using global average | D18: Data from OWID - see "Copy of Land animal numbers" tab
A19: % of livestock production made up by pigs | B19: ='Land animal numbers'!K201 -> #REF! | C19: Using global average | D19: Data from OWID - see "Copy of Land animal numbers" tab
A20: % of livestock production made up by poultry | B20: ='Land animal numbers'!R201 -> #REF! | C20: Using global average | D20: Data from OWID - see "Copy of Land animal numbers" tab
A21: % of livestock production made up by sheep and goats | B21: ='Land animal numbers'!S201 -> #REF! | C21: Using global average | D21: Data from OWID - see "Copy of Land animal numbers" tab
A22: Difference in livestock production - million tons of beef | B22: =$B$14*B18 -> #REF! | C22: Calculation | D22: -
A23: Difference in livestock production - million tons of pork | B23: =$B$14*B19 -> #REF! | C23: Calculation | D23: -
A24: Difference in livestock production - million tons of poultry meat | B24: =$B$14*B20 -> #REF! | C24: Calculation | D24: -
A25: Difference in livestock production - million tons of sheep and goat meat | B25: =$B$14*B21 -> #REF! | C25: Calculation | D25: -
A26: Beef cattle impacted per kg of beef | B26: 0.002744 | C26: Data from Faunalytics | D26: https://osf.io/dkst3
A27: Pigs impacted per kg of pork | B27: 0.010401 | C27: Data from Faunalytics | D27: https://osf.io/dkst3
A28: Chickens* impacted per kg of poultry meat | B28: 0.57586 | C28: Data from Faunalytics *Using chicken as a proxy for all poultry as this is the most produced poultry animal. | D28: https://osf.io/dkst3
A29: Sheep* impacted per kg of sheep and goat meat | B29: =AVERAGE(B26:B27) -> 0.0065725 | C29: Best guess - average of cattle and pigs *Using sheep as a proxy as we have more information on sheep | D29: -
A30: Number of cows impacted by difference in livestock production | B30: =B22*1000000000*B26 -> #REF! | C30: Calculation | D30: -
A31: Number of pigs impacted by difference in livestock production | B31: =B23*1000000000*B27 -> #REF! | C31: Calculation | D31: -
A32: Number of chickens impacted by difference in livestock production | B32: =B24*1000000000*B28 -> #REF! | C32: Calculation | D32: -
A33: Number of sheep impacted by difference in livestock production | B33: =B25*1000000000*B29 -> #REF! | C33: Calculation | D33: -
A34: SADs averted
A35: SADs per beef cow | B35: 21.9 | C35: Note that this SADs estimate is based on a quick estimate only | D35: https://docs.google.com/spreadsheets/d/1_q1jrOiOSs6BNohV5wq5wFrBor1NSkv19AuvV69lPtI/edit?gid=1626888811#gid=1626888811
A36: SADs per pig | B36: 9 | C36: Note that this doesn't account for impacts on sows | D36: https://docs.google.com/spreadsheets/d/1_q1jrOiOSs6BNohV5wq5wFrBor1NSkv19AuvV69lPtI/edit?gid=1626888811#gid=1626888811
A37: SADs per chicken | B37: 1.5 | C37: Assumes broilers are fast growing | D37: https://docs.google.com/spreadsheets/d/1_q1jrOiOSs6BNohV5wq5wFrBor1NSkv19AuvV69lPtI/edit?gid=1626888811#gid=1626888811
A38: SADs per sheep | B38: 2.5 | C38: Note that this SADs estimate is based on a quick estimate only | D38: https://docs.google.com/spreadsheets/d/1_q1jrOiOSs6BNohV5wq5wFrBor1NSkv19AuvV69lPtI/edit?gid=1626888811#gid=1626888811
A39: SADs averted by difference in beef cow production | B39: =B30*B35 -> #REF! | C39: Calculation | D39: -
A40: SADs averted by difference in pig production | B40: =B31*B36 -> #REF! | C40: Calculation | D40: -
A41: SADs averted by difference in chicken cow production | B41: =B32*B37 -> #REF! | C41: Calculation | D41: -
A42: SADs averted by difference in sheep cow production | B42: =B33*B38 -> #REF! | C42: Calculation | D42: -
A43: Expected value of animal impacts (total SADs averted due to intervention) | B43: =SUM(B39:B42)*B9 -> #REF! | C43: Calculation | D43: -
...

Sheet Info
A1: Securing Scale-up Funding for the Alternative Protein Industry - Cost-effectiveness BOTEC
A2: Main CEA tab is an adaptation of Giving Green (2022) CEA, Livestock production, adjusted high-innovation scenario, and GFI's spending are lifted from Giving Green - all errors our own.

Sheet Main CEA
A1: Notes: This is a copy of the "best guess" CEA of GFI created by Giving Green focused on the impact of GFI securing public fundng for alt protein R&D. This CEA only focuses on meat producing land animals as the original analysis that Giving Green's CEA was based on only considered "livestock". Note that this has a global focus. The only differences I have made are: 1. I have used a 1.4% discount for future benefits. 2. I model animal welfare impacts in addition to the climate impacts that were already modelled by Giving Green. 3. In this copy of the CEA I also play around with some adjustments to the model detailed in rows 63-73.
B2: Parameter | C2: Notes | D2: Source
A3: Cost
A4: GFI's budget, 2016-2022 | B4: =sum('GFIs spending'!B5:B11) -> 101130900 | C4: Total spending over 2016-2022 period | D4: Giving Green CEA
A5: % of GFI budget spent on lobbying | B5: =(3497823/31037374) -> 0.11269713 | C5: Note that this also includes lobbying on labelling and creating a clear regulatory pathway for cultivated products | D5: GFI 2023 Form 990
A6: GFI's budget, 2016-2022 spent on lobbying | B6: =B4*B5 -> 11397162 | C6: Calculation | D6: -
A8: Discounts
A9: Change in probability of moving from low- to high-innovation scenario due to securing public funding for AP R&D | B9: =AVERAGE(5%,20%) -> 0.125 | C9: Guess - 5-20% | D9: Giving Green CEA
A10: Percent impact that GFI has on securing public funding for AP R&D | B10: =AVERAGE(0.5%,2.5%) -> 0.015 | C10: Guess - 0.5-2.5% | D10: Giving Green CEA
A11: Change in probability of moving to the high-innovation scenario due to GFI | B11: =B9*B10 -> 0.001875 | C11: Calculation | D11: -
A12: Effectiveness adjustment for marginal donation going to international efforts instead of US-based R&D | B12: 1 | C12: Guess | D12: Giving Green CEA
A14: Impacts | B14: Best guess
A15: # of years before the high-innovation scenario is roughly similar to BAU in the absence of GFI | B15: 15 | C15: Guess | D15: Giving Green CEA
A16: The difference in livestock production between adjusted high- and adjusted low-innovation scenarios over years of interest (million tons per year) | B16: {=NPV(0.014,'Livestock production'!F8:F21)} -> 378.35482 | C16: Calculation | D16: Giving Green CEA
A18: Animal impacts
A19: Number of animals
A20: % of livestock production made up by beef cows | B20: ='Animal production data (tonnage'!J202 -> 0.21474368 | C20: Using global weighted average | D20: Data from OWID - see "Animal production data (tonnage)" tab
A21: % of livestock production made up by pigs | B21: ='Animal production data (tonnage'!K202 -> 0.33761369 | C21: Using global weighted average | D21: Data from OWID - see "Animal production data (tonnage)" tab
A22: % of livestock production made up by poultry | B22: ='Animal production data (tonnage'!L202 -> 0.39290121 | C22: Using global weighted average | D22: Data from OWID - see "Animal production data (tonnage)" tab
A23: % of livestock production made up by sheep and goats | B23: ='Animal production data (tonnage'!I202 -> 0.054741422 | C23: Using global weighted average | D23: Data from OWID - see "Animal production data (tonnage)" tab
A24: Difference in livestock production - million tons of beef | B24: =$B$16*B20 -> 81.249307 | C24: Calculation | D24: -
A25: Difference in livestock production - million tons of pork | B25: =$B$16*B21 -> 127.73777 | C25: Calculation | D25: -
A26: Difference in livestock production - million tons of poultry meat | B26: =$B$16*B22 -> 148.65606 | C26: Calculation | D26: -
A27: Difference in livestock production - million tons of sheep and goat meat | B27: =$B$16*B23 -> 20.711681 | C27: Calculation | D27: -
A28: Beef cattle impacted per kg of beef | B28: 0.002744 | C28: Data from Faunalytics | D28: https://osf.io/dkst3
A29: Pigs impacted per kg of pork | B29: 0.010401 | C29: Data from Faunalytics | D29: https://osf.io/dkst3
A30: Chickens* impacted per kg of poultry meat | B30: 0.57586 | C30: Data from Faunalytics *Using chicken as a proxy for all poultry as this is the most produced poultry animal. | D30: https://osf.io/dkst3
A31: Sheep* impacted per kg of sheep and goat meat | B31: =AVERAGE(B28:B29) -> 0.0065725 | C31: Best guess - average of cattle and pigs *Using sheep as a proxy as we have more information on sheep | D31: -
A32: Number of cows impacted by difference in livestock production | B32: =B24*1000000000*B28 -> 2.229481e+08 | C32: Calculation | D32: -
A33: Number of pigs impacted by difference in livestock production | B33: =B25*1000000000*B29 -> 1328600511 | C33: Calculation | D33: -
A34: Number of chickens impacted by difference in livestock production | B34: =B26*1000000000*B30 -> 85605081334 | C34: Calculation | D34: -
A35: Number of sheep impacted by difference in livestock production | B35: =B27*1000000000*B31 -> 1.3612752e+08 | C35: Calculation | D35: -
A36: SADs averted
A37: SADs per beef cow | B37: 21.9 | C37: Note that this SADs estimate is based on a quick estimate only | D37: https://docs.google.com/spreadsheets/d/1_q1jrOiOSs6BNohV5wq5wFrBor1NSkv19AuvV69lPtI/edit?gid=1626888811#gid=1626888811
A38: SADs per pig | B38: 9 | C38: Note that this doesn't account for impacts on sows | D38: https://docs.google.com/spreadsheets/d/1_q1jrOiOSs6BNohV5wq5wFrBor1NSkv19AuvV69lPtI/edit?gid=1626888811#gid=1626888811
A39: SADs per chicken | B39: 1.5 | C39: Assumes broilers are fast growing | D39: https://docs.google.com/spreadsheets/d/1_q1jrOiOSs6BNohV5wq5wFrBor1NSkv19AuvV69lPtI/edit?gid=1626888811#gid=1626888811
A40: SADs per sheep | B40: 2.5 | C40: Note that this SADs estimate is based on a quick estimate only | D40: https://docs.google.com/spreadsheets/d/1_q1jrOiOSs6BNohV5wq5wFrBor1NSkv19AuvV69lPtI/edit?gid=1626888811#gid=1626888811
A41: SADs averted by difference in beef cow production | B41: =B32*B37 -> 4882563341 | C41: Calculation | D41: -
A42: SADs averted by difference in pig production | B42: =B33*B38 -> 11957404595 | C42: Calculation | D42: -
A43: SADs averted by difference in chicken production | B43: =B34*B39 -> 128407622001 | C43: Calculation | D43: -
...

Sheet Livestock production
A1: Notes: Data on livestock production under high- and low-innovation scenarios were extracted from Vivid Economics' report on protein innovation. The high-innovation scenario considers high investment into AP R&D while the low-innovation scenario only considers market-driven AP R&D. We believe that Vivid Economics' estimates for cellular agriculture production are optimistic so we adjusted production under the high-innovation case upwards (see "Adjusted high-innovation scenario"). We also believe that the low-innovation scenario may be unrealistic because there has been increased public funding for APs and they do not solely rely on market forces. Therefore we adjusted livestock production under the low innovation scenario downward. We assumed that the adjusted low-innovation livestock production would be the average between the adjusted high- and low-innovation scenarios.
A3: Table 1: Projections of livestock production under high- and low-innovation scenarios.
B4: Livestock production (million metric tons per year)
A5: Year | B5: High innovation | C5: Low innovation | D5: High innovation (adj) | E5: Low innovation (adj) | F5: Difference
A6: 2020 | B6: 326.78571 | C6: 326.78571 | D6: ='Adjusted high-innovation scenar'!I5 -> 326.78571 | E6: =AVERAGE(C6:D6) -> 326.78571
A7: 2021 | B7: 326.78571 | C7: 335.06944 | D7: ='Adjusted high-innovation scenar'!I6 -> 326.78571 | E7: =AVERAGE(C7:D7) -> 330.92758
A8: 2022 | B8: 326.78571 | C8: 341.26984 | D8: ='Adjusted high-innovation scenar'!I7 -> 326.78571 | E8: =AVERAGE(C8:D8) -> 334.02778 | F8: =E8-D8 -> 7.2420635
A9: 2023 | B9: 326.78571 | C9: 348.71032 | D9: ='Adjusted high-innovation scenar'!I8 -> 326.78571 | E9: =AVERAGE(C9:D9) -> 337.74802 | F9: =E9-D9 -> 10.962302
A10: 2024 | B10: 326.78571 | C10: 354.91071 | D10: ='Adjusted high-innovation scenar'!I9 -> 326.78571 | E10: =AVERAGE(C10:D10) -> 340.84821 | F10: =E10-D10 -> 14.0625
A11: 2025 | B11: 326.78571 | C11: 362.35119 | D11: ='Adjusted high-innovation scenar'!I10 -> 326.78571 | E11: =AVERAGE(C11:D11) -> 344.56845 | F11: =E11-D11 -> 17.782738
A12: 2026 | B12: 321.42857 | C12: 369.79167 | D12: ='Adjusted high-innovation scenar'!I11 -> 324.05222 | E12: =AVERAGE(C12:D12) -> 346.92194 | F12: =E12-D12 -> 22.869725
A13: 2027 | B13: 312.5 | C13: 375.99206 | D13: ='Adjusted high-innovation scenar'!I12 -> 320.3444 | E13: =AVERAGE(C13:D13) -> 348.16823 | F13: =E13-D13 -> 27.82383
A14: 2028 | B14: 305.35714 | C14: 382.19246 | D14: ='Adjusted high-innovation scenar'!I13 -> 321.08212 | E14: =AVERAGE(C14:D14) -> 351.63729 | F14: =E14-D14 -> 30.555171
A15: 2029 | B15: 298.21429 | C15: 388.39286 | D15: ='Adjusted high-innovation scenar'!I14 -> 323.17246 | E15: =AVERAGE(C15:D15) -> 355.78266 | F15: =E15-D15 -> 32.6102
A16: 2030 | B16: 289.28571 | C16: 395.83333 | D16: ='Adjusted high-innovation scenar'!I15 -> 324.62478 | E16: =AVERAGE(C16:D16) -> 360.22906 | F16: =E16-D16 -> 35.604277
A17: 2031 | B17: 276.78571 | C17: 400.79365 | D17: ='Adjusted high-innovation scenar'!I16 -> 323.13275 | E17: =AVERAGE(C17:D17) -> 361.9632 | F17: =E17-D17 -> 38.830449
A18: 2032 | B18: 262.5 | C18: 405.75397 | D18: ='Adjusted high-innovation scenar'!I17 -> 321.12358 | E18: =AVERAGE(C18:D18) -> 363.43877 | F18: =E18-D18 -> 42.315195
A19: 2033 | B19: 248.21429 | C19: 411.95437 | D19: ='Adjusted high-innovation scenar'!I18 -> 320.26929 | E19: =AVERAGE(C19:D19) -> 366.11183 | F19: =E19-D19 -> 45.842537
... A26: 2040 | B26: 189.28571 | C26: 452.87698 | D26: ='Adjusted high-innovation scenar'!I25 -> 337.80757 | E26: =AVERAGE(C26:D26) -> 395.34228 | F26: =E26-D26 -> 57.534709
A27: 2041 | B27: 182.14286 | C27: 459.07738
A28: 2042 | B28: 173.21429 | C28: 465.27778
A29: 2043 | B29: 167.85714 | C29: 468.99802
A30: 2044 | B30: 158.92857 | C30: 475.19841
A31: 2045 | B31: 151.78571 | C31: 480.15873
A32: 2046 | B32: 151.78571 | C32: 485.11905
A33: 2047 | B33: 151.78571 | C33: 490.07937
A34: 2048 | B34: 151.78571 | C34: 495.03968
A35: 2049 | B35: 150 | C35: 500
A36: 2050 | B36: 148.21429 | C36: 504.96032
A38: Table 2: Calculating the conversion factor between emissions and livestock production
B39: Parameter | C39: Notes
A40: Difference in high- and low-innovation scenarios' livestock production in 2050 (million metric tons/yr) | B40: =C36-B36 -> 356.74603 | C40: Calculation
A41: Greenhouse reduction in 2050 (tCO2e) | B41: =5*10^9 -> 5000000000 | C41: Input
A42: Conversion factor between emissions and livestock production (tCO2e/million metric tons) | B42: =B41/$B$40 -> 14015573 | C42: Calculation

Sheet Adjusted high-innovation scenar
A1: Note: We adjusted Vivid Economics' estimates for conventional livestock production under the high-innovation scenario upward because we believe that its model may be too optimistic about cultivated meat production.
A3: Table 1: Calculations for cellular agriculture and conventional livestock production (high-innovation scenario) (million metric tons per year)
A4: Year | B4: Conventional livestock and dairy | C4: Conventional livestock | D4: Conventional dairy | E4: Conventional livestock and dairy + cellular agriculture | F4: Cellular agriculture, livestock and dairy | G4: Cellular agriculture, livestock only | H4: Adjusted cellular agriculture, livestock only | I4: Adjusted conventional livestock
A5: 2019.9752 | B5: 434.66334 | C5: 326.78571 | D5: =B5-C5 -> 107.87763 | E5: 434.66334 | F5: =E5-B5 -> 0 | G5: =C5/B5*F5 -> 0 | H5: =$B$27*G5 -> 0 | I5: =(G5-H5)+C5 -> 326.78571
A6: 2020.9752 | B6: 434.66334 | C6: 326.78571 | D6: =B6-C6 -> 107.87763 | E6: 434.66334 | F6: =E6-B6 -> 0 | G6: =C6/B6*F6 -> 0 | H6: =$B$27*G6 -> 0 | I6: =(G6-H6)+C6 -> 326.78571
A7: 2022.0151 | B7: 436.40898 | C7: 326.78571 | D7: =B7-C7 -> 109.62326 | E7: 436.40898 | F7: =E7-B7 -> 0 | G7: =C7/B7*F7 -> 0 | H7: =$B$27*G7 -> 0 | I7: =(G7-H7)+C7 -> 326.78571
A8: 2022.9751 | B8: 436.40898 | C8: 326.78571 | D8: =B8-C8 -> 109.62326 | E8: 436.40898 | F8: =E8-B8 -> 0 | G8: =C8/B8*F8 -> 0 | H8: =$B$27*G8 -> 0 | I8: =(G8-H8)+C8 -> 326.78571
A9: 2023.9751 | B9: 436.40898 | C9: 326.78571 | D9: =B9-C9 -> 109.62326 | E9: 436.40898 | F9: =E9-B9 -> 0 | G9: =C9/B9*F9 -> 0 | H9: =$B$27*G9 -> 0 | I9: =(G9-H9)+C9 -> 326.78571
A10: 2024.9751 | B10: 436.40898 | C10: 326.78571 | D10: =B10-C10 -> 109.62326 | E10: 436.40898 | F10: =E10-B10 -> 0 | G10: =C10/B10*F10 -> 0 | H10: =$B$27*G10 -> 0 | I10: =(G10-H10)+C10 -> 326.78571
A11: 2026.0156 | B11: 427.6808 | C11: 321.42857 | D11: =B11-C11 -> 106.25223 | E11: 431.17207 | F11: =E11-B11 -> 3.4912718 | G11: =C11/B11*F11 -> 2.6239067 | H11: =$B$27*G11 -> 0.00026239067 | I11: =(G11-H11)+C11 -> 324.05222
A12: 2026.9762 | B12: 417.20698 | C12: 312.5 | D12: =B12-C12 -> 104.70698 | E12: 427.6808 | F12: =E12-B12 -> 10.473815 | G12: =C12/B12*F12 -> 7.8451883 | H12: =$B$27*G12 -> 0.00078451883 | I12: =(G12-H12)+C12 -> 320.3444
A13: 2027.9768 | B13: 406.73317 | C13: 305.35714 | D13: =B13-C13 -> 101.37602 | E13: 427.6808 | F13: =E13-B13 -> 20.947631 | G13: =C13/B13*F13 -> 15.726548 | H13: =$B$27*G13 -> 0.0015726548 | I13: =(G13-H13)+C13 -> 321.08212
A14: 2028.9774 | B14: 396.25935 | C14: 298.21429 | D14: =B14-C14 -> 98.045066 | E14: 429.42643 | F14: =E14-B14 -> 33.167082 | G14: =C14/B14*F14 -> 24.960667 | H14: =$B$27*G14 -> 0.0024960667 | I14: =(G14-H14)+C14 -> 323.17246
A15: 2029.978 | B15: 385.78554 | C15: 289.28571 | D15: =B15-C15 -> 96.499822 | E15: 432.91771 | F15: =E15-B15 -> 47.13217 | G15: =C15/B15*F15 -> 35.342599 | H15: =$B$27*G15 -> 0.0035342599 | I15: =(G15-H15)+C15 -> 324.62478
A16: 2030.9792 | B16: 364.83791 | C16: 276.78571 | D16: =B16-C16 -> 88.052191 | E16: 425.93516 | F16: =E16-B16 -> 61.097257 | G16: =C16/B16*F16 -> 46.351675 | H16: =$B$27*G16 -> 0.0046351675 | I16: =(G16-H16)+C16 -> 323.13275
... A25: 2039.9856 | B25: 251.37157 | C25: 189.28571 | D25: =B25-C25 -> 62.085857 | E25: 448.62843 | F25: =E25-B25 -> 197.25686 | G25: =C25/B25*F25 -> 148.53671 | H25: =$B$27*G25 -> 0.014853671 | I25: =(G25-H25)+C25 -> 337.80757
A27: Adjustment factor | B27: =10^-4 -> 0.0001

Sheet GFIs spending
A1: Note: Information on GFI's annual revenue.
A3: Table 2: GFI's budget, assuming that its spending increases linearly
A4: Year | B4: Spending | C4: Note
A5: 2016 | B5: 2957969 | C5: Input
A6: 2017 | B6: 5291596 | C6: Input
A7: 2018 | B7: 8359313 | C7: Input
A8: 2019 | B8: 21598428 | C8: Input
A9: 2020 | B9: 18923594 | C9: Input
A10: 2021 | B10: =(9+5)*10^6 -> 14000000 | C10: Input
A11: 2022 | B11: =30*10^6 -> 30000000 | C11: Input

Sheet Animal production data (tonnage
A1: Country | B1: Year | C1: Sheep and goat (tonnes) | D1: Beef and buffalo (tonnes) | E1: Pig (tonnes) | F1: Poultry (tonnes) | G1: Total tonnage produced | H1: % of world production | I1: % sheep production | J1: % beef production | K1: % pig production | L1: % poultry production
A2: Afghanistan | B2: 2023 | C2: 148165.64 | D2: 71330.38 | E2: 0 | F2: 28796.08 | G2: =SUM(C2:F2) -> 248292.1 | H2: =G2/$G$202 -> 0.0006686176 | I2: =C2/$G2 -> 0.59673924 | J2: =D2/$G2 -> 0.28728413 | K2: =E2/$G2 -> 0 | L2: =F2/$G2 -> 0.11597663 | N2: Source:
A3: Albania | B3: 2023 | C3: 23138 | D3: 28412 | E3: 6532 | F3: 17967 | G3: =SUM(C3:F3) -> 76049 | H3: =G3/$G$202 -> 0.00020478984 | I3: =C3/$G3 -> 0.30425121 | J3: =D3/$G3 -> 0.37360123 | K3: =E3/$G3 -> 0.085891991 | L3: =F3/$G3 -> 0.23625557 | N3: https://ourworldindata.org/meat-production
A4: Algeria | B4: 2023 | C4: 398936.97 | D4: 138000 | E4: 106.59 | F4: 458093.9 | G4: =SUM(C4:F4) -> 995137.46 | H4: =G4/$G$202 -> 0.0026797728 | I4: =C4/$G4 -> 0.4008863 | J4: =D4/$G4 -> 0.13867431 | K4: =E4/$G4 -> 0.00010711083 | L4: =F4/$G4 -> 0.46033228
A5: Angola | B5: 2023 | C5: 23704.96 | D5: 105926 | E5: 179370.55 | F5: 60236.37 | G5: =SUM(C5:F5) -> 369237.88 | H5: =G5/$G$202 -> 0.0009943085 | I5: =C5/$G5 -> 0.064199697 | J5: =D5/$G5 -> 0.28687739 | K5: =E5/$G5 -> 0.48578588 | L5: =F5/$G5 -> 0.16313703
A6: Antigua and Barbuda | B6: 2023 | C6: 3.64 | D6: 39.61 | E6: 44.09 | F6: 17.06 | G6: =SUM(C6:F6) -> 104.4 | H6: =G6/$G$202 -> 2.8113531e-07 | I6: =C6/$G6 -> 0.0348659 | J6: =D6/$G6 -> 0.37940613 | K6: =E6/$G6 -> 0.42231801 | L6: =F6/$G6 -> 0.16340996
A7: Argentina | B7: 2023 | C7: 50204.78 | D7: 3287045.8 | E7: 762163.56 | F7: 2328563 | G7: =SUM(C7:F7) -> 6427977.1 | H7: =G7/$G$202 -> 0.017309687 | I7: =C7/$G7 -> 0.0078103545 | J7: =D7/$G7 -> 0.51136551 | K7: =E7/$G7 -> 0.11856974 | L7: =F7/$G7 -> 0.3622544
A8: Armenia | B8: 2023 | C8: 10926.35 | D8: 60500 | E8: 15100 | F8: 13800 | G8: =SUM(C8:F8) -> 100326.35 | H8: =G8/$G$202 -> 0.00027016552 | I8: =C8/$G8 -> 0.10890808 | J8: =D8/$G8 -> 0.60303201 | K8: =E8/$G8 -> 0.15050881 | L8: =F8/$G8 -> 0.1375511
A9: Australia | B9: 2023 | C9: 887021 | D9: 2236234 | E9: 466466 | F9: 1463274.4 | G9: =SUM(C9:F9) -> 5052995.4 | H9: =G9/$G$202 -> 0.013607045 | I9: =C9/$G9 -> 0.1755436 | J9: =D9/$G9 -> 0.44255611 | K9: =E9/$G9 -> 0.092314749 | L9: =F9/$G9 -> 0.28958554
A10: Austria | B10: 2023 | C10: 7590 | D10: 204580 | E10: 454260 | F10: 149492.14 | G10: =SUM(C10:F10) -> 815922.14 | H10: =G10/$G$202 -> 0.0021971698 | I10: =C10/$G10 -> 0.0093023582 | J10: =D10/$G10 -> 0.25073471 | K10: =E10/$G10 -> 0.5567443 | L10: =F10/$G10 -> 0.18321863
A11: Azerbaijan | B11: 2023 | C11: 88946 | D11: 152787 | E11: 492 | F11: 137501 | G11: =SUM(C11:F11) -> 379726 | H11: =G11/$G$202 -> 0.0010225516 | I11: =C11/$G11 -> 0.23423732 | J11: =D11/$G11 -> 0.40236118 | K11: =E11/$G11 -> 0.0012956711 | L11: =F11/$G11 -> 0.36210583
A12: Bahamas | B12: 2023 | C12: 104.42 | D12: 18.65 | E12: 323.92 | F12: 6003.87 | G12: =SUM(C12:F12) -> 6450.86 | H12: =G12/$G$202 -> 1.7371308e-05 | I12: =C12/$G12 -> 0.016186989 | J12: =D12/$G12 -> 0.0028910874 | K12: =E12/$G12 -> 0.05021346 | L12: =F12/$G12 -> 0.93070846
A13: Bahrain | B13: 2023 | C13: 26694.03 | D13: 782.41 | E13: 0 | F13: 8788.63 | G13: =SUM(C13:F13) -> 36265.07 | H13: =G13/$G$202 -> 9.765701e-05 | I13: =C13/$G13 -> 0.73608103 | J13: =D13/$G13 -> 0.021574755 | K13: =E13/$G13 -> 0 | L13: =F13/$G13 -> 0.24234422
A14: Bangladesh | B14: 2023 | C14: 247632.56 | D14: 209642.11 | E14: 0 | F14: 291126.4 | G14: =SUM(C14:F14) -> 748401.07 | H14: =G14/$G$202 -> 0.0020153445 | I14: =C14/$G14 -> 0.33088216 | J14: =D14/$G14 -> 0.28012 | K14: =E14/$G14 -> 0 | L14: =F14/$G14 -> 0.38899784
A15: Barbados | B15: 2023 | C15: 124 | D15: 166.06 | E15: 2575.87 | F15: 15184.04 | G15: =SUM(C15:F15) -> 18049.97 | H15: =G15/$G$202 -> 4.8606168e-05 | I15: =C15/$G15 -> 0.0068698175 | J15: =D15/$G15 -> 0.0092000153 | K15: =E15/$G15 -> 0.14270772 | L15: =F15/$G15 -> 0.84122245
... A25: Brunei | B25: 2023 | C25: 51.98 | D25: 1516.84 | E25: 30.29 | F25: 29161.13 | G25: =SUM(C25:F25) -> 30760.24 | H25: =G25/$G$202 -> 8.2833235e-05 | I25: =C25/$G25 -> 0.0016898438 | J25: =D25/$G25 -> 0.049311709 | K25: =E25/$G25 -> 0.00098471273 | L25: =F25/$G25 -> 0.94801373
A26: Bulgaria | B26: 2023 | C26: 9220 | D26: 17373 | E26: 79630 | G26: =SUM(C26:F26) -> 106223 | H26: =G26/$G$202 -> 0.00028604441 | I26: =C26/$G26 -> 0.086798528 | J26: =D26/$G26 -> 0.16355215 | K26: =E26/$G26 -> 0.74964932 | L26: =F26/$G26 -> 0
A27: Burkina Faso | B27: 2023 | C27: 50976.95 | D27: 132162.31 | E27: 184788.77 | F27: 152711 | G27: =SUM(C27:F27) -> 520639.03 | H27: =G27/$G$202 -> 0.0014020117 | I27: =C27/$G27 -> 0.097912271 | J27: =D27/$G27 -> 0.25384634 | K27: =E27/$G27 -> 0.35492685 | L27: =F27/$G27 -> 0.29331454
A28: Burundi | B28: 2023 | C28: 4179.28 | D28: 16155.77 | E28: 12301.97 | F28: 9229.33 | G28: =SUM(C28:F28) -> 41866.35 | H28: =G28/$G$202 -> 0.00011274051 | I28: =C28/$G28 -> 0.099824322 | J28: =D28/$G28 -> 0.38588914 | K28: =E28/$G28 -> 0.29383909 | L28: =F28/$G28 -> 0.22044745
A29: Cambodia | B29: 2023 | C29: 0 | D29: 58979.71 | E29: 103584.95 | F29: 26803.2 | G29: =SUM(C29:F29) -> 189367.86 | H29: =G29/$G$202 -> 0.00050994246 | I29: =C29/$G29 -> 0 | J29: =D29/$G29 -> 0.31145576 | K29: =E29/$G29 -> 0.54700386 | L29: =F29/$G29 -> 0.14154039
A30: Cameroon | B30: 2023 | C30: 44230.36 | D30: 120841.82 | E30: 50155.2 | F30: 117851.96 | G30: =SUM(C30:F30) -> 333079.34 | H30: =G30/$G$202 -> 0.00089693836 | I30: =C30/$G30 -> 0.13279227 | J30: =D30/$G30 -> 0.36280191 | K30: =E30/$G30 -> 0.15058034 | L30: =F30/$G30 -> 0.35382549
A31: Canada | B31: 2023 | C31: 17647 | D31: 1347831 | E31: 2286725 | F31: 1585931.6 | G31: =SUM(C31:F31) -> 5238134.6 | H31: =G31/$G$202 -> 0.0141056 | I31: =C31/$G31 -> 0.0033689474 | J31: =D31/$G31 -> 0.25731126 | K31: =E31/$G31 -> 0.43655331 | L31: =F31/$G31 -> 0.30276648
A32: Cape Verde | B32: 2023 | C32: 756.58 | D32: 705.76 | E32: 2542.63 | F32: 557.11 | G32: =SUM(C32:F32) -> 4562.08 | H32: =G32/$G$202 -> 1.2285075e-05 | I32: =C32/$G32 -> 0.16584102 | J32: =D32/$G32 -> 0.15470136 | K32: =E32/$G32 -> 0.55734007 | L32: =F32/$G32 -> 0.12211754
A33: Central African Republic | B33: 2023 | C33: 24603.73 | D33: 104706.11 | E33: 19353.44 | F33: 6439.79 | G33: =SUM(C33:F33) -> 155103.07 | H33: =G33/$G$202 -> 0.00041767194 | I33: =C33/$G33 -> 0.15862826 | J33: =D33/$G33 -> 0.67507439 | K33: =E33/$G33 -> 0.12477793 | L33: =F33/$G33 -> 0.041519423
A34: Chad | B34: 2023 | C34: 396602.22 | D34: 554249.75 | E34: 2467.72 | F34: 6538.31 | G34: =SUM(C34:F34) -> 959858 | H34: =G34/$G$202 -> 0.0025847699 | I34: =C34/$G34 -> 0.41318843 | J34: =D34/$G34 -> 0.5774289 | K34: =E34/$G34 -> 0.0025709219 | L34: =F34/$G34 -> 0.0068117472
A35: Chile | B35: 2023 | C35: 13711.43 | D35: 187564.11 | E35: 582651.6 | F35: 759948.3 | G35: =SUM(C35:F35) -> 1543875.4 | H35: =G35/$G$202 -> 0.0041574512 | I35: =C35/$G35 -> 0.0088811763 | J35: =D35/$G35 -> 0.12148915 | K35: =E35/$G35 -> 0.37739547 | L35: =F35/$G35 -> 0.49223421
A36: China | B36: 2023 | C36: 5312600 | D36: 7526800 | E36: 57943200 | F36: 25630000 | G36: =SUM(C36:F36) -> 96412600 | H36: =G36/$G$202 -> 0.25962631 | I36: =C36/$G36 -> 0.055102756 | J36: =D36/$G36 -> 0.078068634 | K36: =E36/$G36 -> 0.60099199 | L36: =F36/$G36 -> 0.26583662
A37: Colombia | B37: 2023 | C37: 902 | D37: 718630 | E37: 550959 | F37: 1817130 | G37: =SUM(C37:F37) -> 3087621 | H37: =G37/$G$202 -> 0.0083145527 | I37: =C37/$G37 -> 0.0002921343 | J37: =D37/$G37 -> 0.23274553 | K37: =E37/$G37 -> 0.17844127 | L37: =F37/$G37 -> 0.58852107
A38: Comoros | B38: 2023 | C38: 473.14 | D38: 1233.44 | E38: 0 | F38: 576.7 | G38: =SUM(C38:F38) -> 2283.28 | H38: =G38/$G$202 -> 6.1485694e-06 | I38: =C38/$G38 -> 0.20721944 | J38: =D38/$G38 -> 0.54020532 | K38: =E38/$G38 -> 0 | L38: =F38/$G38 -> 0.25257524
... A201: Zimbabwe | B201: 2023 | C201: 37816.56 | D201: 743164.4 | E201: 15991.79 | F201: 97957.17 | G201: =SUM(C201:F201) -> 894929.92 | H201: =G201/$G$202 -> 0.0024099272 | I201: =C201/$G201 -> 0.042256448 | J201: =D201/$G201 -> 0.83041631 | K201: =E201/$G201 -> 0.017869321 | L201: =F201/$G201 -> 0.10945792
G202: =SUM(G2:G201) -> 3.7135143e+08 | I202: =IFERROR(__xludf.DUMMYFUNCTION("AVERAGE.WEIGHTED(I2:I201,$H$2:$H$201)"),0.05474142213174702) -> 0.054741422 | J202: =IFERROR(__xludf.DUMMYFUNCTION("AVERAGE.WEIGHTED(J2:J201,$H$2:$H$201)"),0.2147436816679707) -> 0.21474368 | K202: =IFERROR(__xludf.DUMMYFUNCTION("AVERAGE.WEIGHTED(K2:K201,$H$2:$H$201)"),0.3376136903115392) -> 0.33761369 | L202: =IFERROR(__xludf.DUMMYFUNCTION("AVERAGE.WEIGHTED(L2:L201,$H$2:$H$201)"),0.39290120588874305) -> 0.39290121
