Workbook

Sheet Main CEA
A1: Inputs | B1: Expected | C1: Description | G1: Source
A2: Costs
A3: Fixed Costs - Year 1 | B3: 125000 | C3: Best guess (Held constant in all CEAs) | G3: -
A4: Fixed Costs - Scale | B4: 225000 | C4: Best guess (Held constant in all CEAs) | G4: -
A5: Start up costs - FACILITY SET UP | B5: ='Cost Estimates'!B62 -> 10683.333 | C5: See Cost Estimates, for ~11,000 capacity | G5: -
A6: Start up costs - TRAINING P/TREATMENT adj. for turnover | B6: ='Cost Estimates'!B65 -> 3.381 | C6: See Cost Estimates | G6: -
A7: Cost estimate p/treatment - In Hospital | B7: ='Cost Estimates'!B44 -> 264.46365 | C7: See Cost Estimates | G7: -
A8: Population Data & Other Baselines
A9: Karachi, Sindh, Pakistan
A10: Approximation of number of births in a large facility x year | B10: 7700 | C10: A large hospital has registered 7,700 births and I think there are larger ones | G10: Frequency of Stillbirths in a Tertiary Care Hospital, Karachi - PMC
A11: Lahore, Punjab, Pakistan
A12: Approximation of number of births in a large facility x year | B12: 15606 | C12: Live births reported in 2018 in Sir Ganga Ram Hospital Lahore | G12: https://www.pc.gov.pk/uploads/crvs_reports/Vital_Statistics_Punja_3-11-20.pdf
A13: Peshawar, Khyber Pakhtunkhwa, Pakistan
A14: Approximation of number of births in a large facility x year | B14: =ROUND(36460/9,0) -> 4051 | C14: 36,460 deliveries were conducted over the 9 year period in the largest tertiary care hospital in Pakistan | G14: TRENDS IN MATERNAL MORTALITY IN TERTIARY CARE HOSPITAL IN PESHAWAR - PAKISTAN
A15: Quetta, Balochistan, Pakistan
A16: Approximation of number of births in a large facility x year | B16: =round(33396/5,0) -> 6679 | C16: 33,396 at Department of Obstetrics and Gynecology unit-4 Bolan Medical Complex Hospital, Quetta, from 1st January 2012 to 31st December, 2016, | G16: Trial of Labour after one Caesarean Section-Five year Experience in a Tertiary Care Hospital, Quetta | Journal of The Society of Obstetricians and Gynaecologists of Pakistan
A17: KC Treatment, Effects & Low Birth Weight Risks
A18: Risk of Death for Low Birth Weight (neonatal) | B18: =Calculations!B13 -> 0.1344366 | C18: Average of estimates, see calculations | G18: -
A19: Mortality Reduction effect due to KC (by discharge) | B19: 0.32 | G19: Kangaroo mother care for preterm or low birth weight infants: A systematic review and meta-analysis
A20: Disability weight of being LBW | B20: 0.106 | C20: Disability weight for "Low birth weight - All sequelae" | G20: GLOBAL BURDEN OF DISEASE 2004 UPDATE: DISABILITY WEIGHTS FOR DISEASES AND CONDITIONS
A21: Life expectancy in Pakistan | B21: 66.1 | G21: Our World in Data, 2021
A22: Morbidity and developmental impact of LBW (DALYs) | B22: =B20*B21 -> 7.0066 | C22: There is substantial evidence that KC has an effect on morbidity, see report | G22: 2022 LSGH - 275 KMC Report DRAFT MF
A23: Morbidity effects | B23: 0.15 | C23: As a best guess, we take the reduction in the risk of sepsis - "There was a 15% reduction in severe infection/sepsis at the latest follow-up (RR 0.85, 95% CI 0.79 to 0.92; 9 trials, 9847 infants; moderate certainty evidence)" | G23: https://www.medrxiv.org/content/10.1101/2022.09.14.22279053v1.full.pdf
A24: Expected KMC | B24: 0.7 | C24: "70% of preterm and low-birthweight babies are estimated to be suitable for KMC" | G24: https://apps.who.int/iris/rest/bitstreams/1148441/retrieve
A25: Low Birth Weight Prevalence | B25: =Calculations!B$6 -> 0.22397846 | C25: Constructed with Demographic and Health Survey Data, see Calculations | G25: Pakistan Demographic and Health Survey 2017-18 [FR354]
A26: Timing
A27: Time spent preparing intervention (year) | B27: 1 | G27: -
A28: Timing to scale in treatment (year) | B28: 4
A29: Number of years charity runs for if unsuccessful | B29: 3 | C29: If after 3 years it looks unlikely the charity will be successful, we assume they will end the operation. Costs after this point will therefore be incurred probabilistically.
A30: % of population reached at scale | B30: 1 | C30: Assumes ward can intake all potential patients
A31: Other Assumptions
A32: Discount rate | B32: 0.04 | G32: -
A33: DALY per neonate death averted | B33: 33.07 | G33: Copy of 2017 GiveWell Cost-Effectiveness Analysis — "standard" moral weights version
A34: Probability of success - Chance charity is able to align stakeholders and set up wards | B34: 0.65 | C34: This is a fairly complex intervention, so I expect it to be at the lower end | G34: -
A35: Baseline Coverage of KC | B35: 0.11 | C35: This is an extremely rough proxy, based on the report % of newborns who were put immediately after birth on the skin of the mother's chest | G35: Pakistan Demographic and Health Survey 2017-18 [FR354]
A36: Chance change would have happened anyways | B36: 0.1 | C36: This is a subjective best guess | G36: -
A37: Calculations - Karachi, Sindh, Pakistan
A38: Year | B38: 1 | C38: 2 | D38: 3 | E38: 4 | F38: 5 | G38: 6 | H38: 7 | I38: 8 | J38: 9 | K38: 10 | L38: 11 | M38: 12 | N38: 13 | O38: 14 | P38: 15 | Q38: 16 | R38: 17 | S38: 18 | T38: 19 | U38: 20 | V38: 21 | W38: 22 | X38: 23 | Y38: 24 | Z38: 25
A39: Scale | B39: =MIN((B38-$B$27)/$B$28,1) -> 0 | C39: =MIN((C38-$B$27)/$B$28,1) -> 0.25 | D39: =MIN((D38-$B$27)/$B$28,1) -> 0.5 | E39: =MIN((E38-$B$27)/$B$28,1) -> 0.75 | F39: =MIN((F38-$B$27)/$B$28,1) -> 1 | G39: =MIN((G38-$B$27)/$B$28,1) -> 1 | H39: =MIN((H38-$B$27)/$B$28,1) -> 1 | I39: =MIN((I38-$B$27)/$B$28,1) -> 1 | ... Z39: =MIN((Z38-$B$27)/$B$28,1) -> 1
A40: Fixed Costs | B40: =B3 -> 125000 | C40: =$B4 -> 225000 | D40: =$B4 -> 225000 | E40: =$B4*$B$34 -> 146250 | F40: =$B4*$B$34 -> 146250 | G40: =$B4*$B$34 -> 146250 | H40: =$B4*$B$34 -> 146250 | I40: =$B4*$B$34 -> 146250 | J40: =$B4*$B$34 -> 146250 | K40: =$B4*$B$34 -> 146250 | L40: =$B4*$B$34 -> 146250 | ... Z40: =$B4*$B$34 -> 146250
...

Sheet Calculations
A1: Weighted Low Birth Weight Prevalence based on Demographic and Health Se
A2: Age of Mother | B2: Percentage less than 2.5 kg among weighed | C2: Number of births in sample
A3: <20 | B3: 0.335 | C3: 972
A4: 20-34 | B4: 0.205 | C4: 8482
A5: 35-49 | B5: 0.275 | C5: 1040
A6: Estimate | B6: =((B3*C3)+(B4*C4)+(B5*C5))/SUM(C3:C5) -> 0.22397846
A7: Weighted Low Birth Weight Counterfactual Mortality
A8: Item | B8: Figure | C8: n | D8: Notes | E8: Source
A9: Estimate 1 | B9: =133/1000 -> 0.133 | C9: 776 | D9: Periurban setting - Bangladesh / Retrospective Cohort Study (n=776) | E9: Neonatal mortality of low-birth-weight infants in Bangladesh. - PMC
A10: Estimate 2 | B10: 0.111 | C10: 885 | D10: Community-based - South Ethiopia / Mixed-method (n=885) | E10: Magnitude and Risk of Dying among Low Birth Weight Neonates in Rural Ethiopia: A Community-Based Cross-Sectional Study - PMC
A11: Estimate 3 | B11: 0.083 | C11: 216 | D11: Public Hospitals - Ethiopia / Prospective Cohort Study (n=216) | E11: The Kaplan Meier estimates of mortality and its predictors among newborns admitted with low birth weight at public hospitals in Ethiopia | PLOS ONE
A12: Estimate 4 | B12: 0.152 | C12: n/a | D12: Meta-analysis | E12: https://academic.oup.com/trstmh/article-abstract/95/6/569/1905057?redirectedFrom=fulltext&login=false#no-access-message
A13: Estimate | B13: =AVERAGE((B9*C9+B10*C10+B11*C11)/SUM(C9:C11),B12) -> 0.1344366 | D13: (Weighted (by n) average of estimates 1-3 + Estimate 4) / 2

Sheet Cost Estimates
A1: Estimates
A2: 1. r.i.c.e model // VARIABLE TREATMENT COSTS
A3: Item | B3: Estimate | C3: Notes | D3: Source
A4: P/Treatment | B4: 455 | C4: Uttar Pradesh, India | D4: Internal
A5: 2. Incremental costs per treatment reported in India // VARIABLE TREATMENT COSTS
A6: Item | B6: Estimate | C6: Notes | D6: Source
A7: P/Treatment | B7: 72 | C7: Average 3 Indian States | D7: Incremental costs of scaling up kangaroo mother care: Results from implementation research in Ethiopia and India - - Acta Paediatrica - Wiley Online Library
A8: 3. Costs per treatment calculated from study // VARIABLE TREATMENT COSTS
A9: Item | B9: Estimate | C9: Notes | D9: Source
A10: Salaries | B10: 11788
A11: Other variable | B11: 7501
A12: Number in treatment arm | B12: 149
A13: P/Treatment | B13: =SUM(B10:B11)/B12 -> 129.45638 | C13: Average 3 Indian States | D13: Incremental costs of scaling up kangaroo mother care: Results from implementation research in Ethiopia and India - - Acta Paediatrica - Wiley Online Library
A14: 4. My estimate // VARIABLE TREATMENT COSTS
A15: Nurse Salary Estimates
A16: Item | B16: Figure | C16: Notes | D16: Source
A17: Estimate 1 PKR | B17: =37500*12 -> 450000 | C17: Average Annual Salary for Nurse 2-5 years experience | D17: Staff Nurse Average Salary in Pakistan 2023 - The Complete Guide
A18: Estimate 2 PKR | B18: 267998.72 | C18: Annual Salary for Assistant Nurse or Midwive | D18: LiST Costing Tool
A19: Average USD | B19: =IFERROR(__xludf.DUMMYFUNCTION("GOOGLEFINANCE(""currency:pkrusd"")*AVERAGE(B17:B18)"),1289.8488012805449) -> 1289.8488
A20: Manager Salary Estimates
A21: Item | B21: Figure | C21: Notes | D21: Source
A22: Estimate 1 PKR | B22: =47100*12 -> 565200 | C22: Average | D22: Nurse Average Salary in Pakistan 2023 - The Complete Guide
A23: Estimate 2 PKR | B23: 353817.84 | C23: Annual Salary for Nurse | D23: LiST Costing Tool
A24: Average USD | B24: =IFERROR(__xludf.DUMMYFUNCTION("GOOGLEFINANCE(""currency:pkrusd"")*AVERAGE(B22:B23)"),1650.9695996919768) -> 1650.9696
A25: Estimate of nurse need and manager need per treatment
A26: Nurse ratio p/treatment | B26: =15/540 -> 0.027777778 | C26: r.i.c.e ratio is ~15 x ~540 treatments
A27: Manager ratio p/treatment | B27: =4/540 -> 0.0074074074 | C27: r.i.c.e ratio is ~4 x ~540 treatments
A28: Assistant ratio/ptreatment | B28: =11/540 -> 0.02037037 | C28: r.i.c.e ratio is ~11 ~540 treatments.
A29: Variable costs p/treatment
A30: Additional consumables | B30: 3.63 | C30: KMC garments (e.g.,cloth wraps) 2 USD + Other consumables 1 USD + Parent education literature 0.63 USD | D30: The cost-savings of implementing kangaroo mother care in Nicaragua
A31: Treatment | B31: =(B19*B26+B24*B27+(B19/2)*B28)+B30 -> 64.825887 | C31: I assume 50% cost of nurse for assistant
A32: 5. WHO Guideline breakdown - followed guidelines for assumed 100 treated // VARIABLE TREATMENT COSTS
A33: Item | B33: Figure | C33: Notes | D33: Source
A34: Beds needed p/100 treated (rounded) | B34: =ROUND(100*(6.61/365)*1.5,0) -> 3 | C34: Expected KMC x (Average length of stay / 365) x 1.5 // 1.5 to account for fluctuations, according to document // Average length of stay is 6.61 days - average of three sources cited | D34: https://apps.who.int/iris/rest/bitstreams/1148441/retrieve | E34: Safety, Effectiveness and Barriers to Follow-up Using an ‘Early Discharge’ Kangaroo Care Policy in a Resource Poor Setting | F34: Kangaroo care in pre-term or low birth weight babies in a postnatal ward | G34: Maternal experience of intermittent kangaroo mother care for late preterm infants: a mixed-methods study in four postnatal wards in China - PMC
A35: Number staff needed p/100 treated (rounded) | B35: =ROUND((B34/8)*3*(7/5),0) -> 2 | C35: Total beds needed / 8 x (# shifts/day) x (7/#days worked/week) // For a basic KMC ward assume 1 nurse or equivalent staff for 8–10 beds | D35: https://apps.who.int/iris/rest/bitstreams/1148441/retrieve
A36: Staff cost per treated + Additional Consumables | B36: =(B35/100)*B19+B30 -> 29.426976 | C36: Costs of Nurse and Additional consumables from 4. My Estimate
A37: Final estimate // VARIABLE TREATMENT COSTS
A38: Total | B38: Number | C38: Weight
A39: Estimate 1 | B39: =B4 -> 455 | C39: 12 | D39: We think that this is likely to be the most accurate depiction of a programme like this.
A40: Estimate 2 | B40: =B7 -> 72 | C40: 3
...
