Workbook

Sheet Summary
B2: KAT Germany | C2: RSPCA UK | D2: UEP USA | E2: AVG
A3: Discounted costs | B3: ='KAT Germany'!B48 -> 2242439.5 | C3: ='RSPCA UK'!B48 -> 2242439.5 | D3: ='UEP USA'!B50 -> 2242439.5
A4: Discounted benefits | B4: ='KAT Germany'!B49 -> 2.3312454e+08 | C4: ='RSPCA UK'!B49 -> 81545894 | D4: ='UEP USA'!B51 -> 2.0813449e+08 | E4: =AVERAGE(B4:D4) -> 1.7426831e+08
A5: SADs averted/$ | B5: ='KAT Germany'!B50 -> 103.96023 | C5: ='RSPCA UK'!B50 -> 36.364813 | D5: ='UEP USA'!B52 -> 92.816097 | E5: =AVERAGE(B5:D5) -> 77.713715

Sheet KAT Germany
A1: Inputs | B1: Expected | C1: Description | G1: Source
A2: Costs
A3: Fixed costs (Year 1) | B3: 130000 | C3: Held constant across all CEAs | G3: -
A4: Fixed costs (At scale) | B4: 280000 | C4: Held constant across all CEAs | G4: -
A5: Variable costs - Cost of working with certifiers | B5: =(89931*2/3)+AVERAGE(357000,498000,285000,435000,90554,213500,237043,300000) -> 361966.12 | C5: How much ALI has spent on their certifier campaigns over the last 18 months. Adjusted to reflect costs over 1 year. + How much OP has given to certifiers on average to get them to update their standards. | G5: https://animalcharityevaluators.org/charity-review/ciftlik-hayvanlarini-koruma-dernegi/#c2 https://animalcharityevaluators.org/charity-review/shrimp-welfare-project/#c2 https://animalcharityevaluators.org/charity-review/sinergia-animal/#c2 https://animalcharityevaluators.org/charity-review/the-humane-league/#c2 https://docs.google.com/document/d/1UHLMl1avIl7Sfxm-svVLbN_QCUdmDHzgsonIqKzN3bc/edit#heading=h.6783mx40fots
A6: Charity years operating | B6: 3 | C6: Assume charity gives up on KAT after 3 years if not successful If successful then runs at Year 1 levels to perform audits and undercover investigations of KAT farms | G6: -
A7: Years until implementation | B7: 3 | C7: KAT updates their certification standards every ~2 years and it was last updated in 2024. So the next round of updates would be published in 2026. This would only be 1 year after the new charity launches, so we assume that they don't impact standards until 2028 which is 3 years after the beginning of the charity. | G7: -
A9: Benefits
A10: Number of layers certified by KAT (2019) | B10: =82000000 -> 82000000 | C10: "In 2019, around 82 million hens in barn, free-range and organic production were registered" | G10: https://www.was-steht-auf-dem-ei.de/en/kat-association/index.php
A11: Of which free range or organic | B11: 0.28 | C11: 18% free range and 10% organic | G11: https://www.thuenen.de/en/thuenen-topics/long-term-policy-concepts/nationale-nutztierstrategie/the-egg-of-columbus#:~:text=Most%20eggs%20are%20now%20barn,floor%20or%20free%2Drange%20husbandry.
A12: Likelihood of affecting all hens | B12: 0.33 | C12: Best guess | G12: -
A13: Likelihood just free range or organic | B13: 0.67 | C13: Best guess | G13: -
A14: Estimated number of layers affected through KAT (2019) | B14: =B10*B13*B11+B10*B12 -> 42443200 | C14: Calculation | G14: -
A15: Growth rate of egg industry | B15: 0.014 | C15: "The Federal Statistical Office (Destatis) also reports that production increased by 1.4% compared with the previous year [2021-22]". Asusming growth rate holds. | G15: https://www.destatis.de/EN/Press/2023/03/PE23_104_413.html#:~:text=Increase%20in%20organic%20eggs%20of,compared%20with%20the%20previous%20year.
A16: Estimated number of layers affected through KAT (2025) | B16: =B14*(1+B15)^6 -> 46135566 | C16: Calculation of number of animals certified using growth rate of egg production in Germany | G16: -
A17: SADs attributed to KBF in aviaries currently | B17: 8.655 | C17: This is using Welfare Footprint's data including a prevalence of 30-100%. | G17: https://docs.google.com/spreadsheets/d/1DssnYoZKFSE3w_-E2PLuOImLUd56JK3JNoO6JHkmTPk/edit?gid=289821833#gid=289821833
A18: KBF prevelence before intervention | B18: 0.65 | C18: KBF prevalence is 30-100% | G18: https://cp.pain-track.org/hens
A19: KBF prevelence after intervention | B19: 0.4 | C19: Best guess on what enforcement will actually be with a target of 25% | G19: -
A20: SADs averted per animal | B20: =B17-(B17/B18)*B19 -> 3.3288462 | C20: Calculation | G20: -
A21: Probability of success | B21: =AVERAGE(5/27,7/10,10/28,3/10,3/28,2/5,2/8,2/10,0.1,0.15,0.1) -> 0.25904281 | C21: We use an average of estimates here: 1. ALI's success rate 2. OpenPhil's success rate 3. Koushik's best guess of 10-15% 4. Vicky's best guess of 10% | G21: 1. ALI's success rate: https://docs.google.com/document/d/1cu4DKdrwczszdyVvTeC_jUgI3eXAF4Dk1ZXUSBsTYac/edit?tab=t.0#heading=h.ujzm6p1i0pzg 2. OP's success rate: https://docs.google.com/document/d/1cu4DKdrwczszdyVvTeC_jUgI3eXAF4Dk1ZXUSBsTYac/edit?tab=t.0#heading=h.6783mx40fots 3-4. Informed best guess
A22: Expected enforcement rate | B22: =AVERAGE(55%,70%) -> 0.625 | C22: Best guess enforcement rate of 55%-70% in the UK and Germany | G22: https://docs.google.com/document/d/1UHLMl1avIl7Sfxm-svVLbN_QCUdmDHzgsonIqKzN3bc/edit#bookmark=id.312v09ueelbp
A23: Farms that drop or swap certifier instead of implementing interventions to reduce KBF | B23: 0.15 | C23: Best guess | G23: -
A24: Discount rate (Costs) | B24: 0.04 | C24: Held constant across all CEAs | G24: -
A25: Baseline discount rate (Benefits) | B25: 0.014 | C25: Held constant across all CEAs | G25: -
A26: Annual chance that this would happen without our intervention | B26: 0.07 | C26: Best guess - I think this is quite unlikely as no one else is campaigning about KBF, but KAT standards seem quite strong so could see them adding this and there is at least one case study of a certifier having this requirement (GAP in the US) | G26: -
A27: Total discount rate (Benefits) | B27: =SUM(B25:B26) -> 0.084 | C27: Calculation - Sum of all discount rates | G27: -
A29: Potential negative externalities
A30: One potential intervention that could be implemented to reduce KBF is delaying the age at first egg (AFE) by 4-6 weeks to give the keel bone more time to fully ossify. It is unclear whether this will be good for hen welfare as it is likely that farmers will increase the length of the production cycle if delaying the age at first egg, which will mean that these animals will spend more time on farms. We assume that the production cycle will be lengthened by 4-6 weeks (the same amount of time that the age at first egg is delayed by).
A31: ="SADs per bird with "&B19&" prevalence of KBF" -> SADs per bird with 0.4 prevalence of KBF | B31: =(B17/B18)*B19 -> 5.3261538 | C31: 11.45472588 SADs per animal in aviary system, where 8.655792412 SADs are caused by 65% prevalence of KBF. If we reduce KBF prevalence to 25%, then total SADs will be ~6.12 SADs per animal
A32: Number of weeks farmed (without delayed AFE) | B32: 72 | C32: Laying hens are farmed for 72 weeks | G32: https://www.ciwf.org.uk/media/5235024/The-life-of-laying-hens.pdf
A33: Number of weeks AFE is delayed | B33: =AVERAGE(4,6) -> 5 | C33: AFE delayed by 4-6 weeks | G33: https://docs.google.com/document/d/1VRx3rD4-6A7Jwc3Inqn6LuAiCoPgxy2rKeocioIg5DU/edit
A34: % increase in production length | B34: =B33/B32 -> 0.069444444 | C34: Calculation: 5/72 | G34: -
A35: SADs per bird with 25% prevalence of KBF with delayed AFE | B35: =B31+(B31*B34) -> 5.6960256 | C35: Calculation: SADs per bird accounting for increased production length | G35: -
A36: Additional SADs caused per bird | B36: =B35-B31 -> 0.36987179 | C36: Calculation | G36: -
A37: Likelihood that farmers will implement this intervention | B37: =AVERAGE(5%,20%) -> 0.125 | C37: Best guess: 5-20% | G37: -
A39: Calculations
A40: Year | B40: 1 | C40: 2 | D40: 3 | E40: 4 | F40: 5 | G40: 6 | H40: 7 | I40: 8 | J40: 9 | K40: 10 | L40: 11 | M40: 12 | N40: 13 | O40: 14 | P40: 15 | Q40: 16 | R40: 17 | S40: 18 | T40: 19 | U40: 20 | V40: 21 | W40: 22 | X40: 23 | Y40: 24 | Z40: 25 | AA40: 26 | AB40: 27 | AC40: 28 | AD40: 29 | AE40: 30 | AF40: 31 | AG40: 32 | AH40: 33 | AI40: 34 | AJ40: 35 | AK40: 36 | AL40: 37 | AM40: 38 | AN40: 39 | AO40: 40 | AP40: 41 | AQ40: 42 | AR40: 43 | AS40: 44 | AT40: 45 | AU40: 46 | AV40: 47 | AW40: 48 | AX40: 49 | AY40: 50
A41: Total Costs | B41: =B3+B5 -> 491966.12 | C41: =$B$4+$B$5 -> 641966.12 | D41: =$B$4+$B$5 -> 641966.12 | E41: =$B$4*$B$21 -> 72531.987 | F41: =$B$4*$B$21 -> 72531.987 | G41: =$B$4*$B$21 -> 72531.987 | H41: =$B$4*$B$21 -> 72531.987 | I41: =$B$4*$B$21 -> 72531.987 | J41: =$B$4*$B$21 -> 72531.987 | K41: =$B$4*$B$21 -> 72531.987 | L41: =$B$4*$B$21 -> 72531.987 | ... P41: =$B$4*$B$21 -> 72531.987 | Q41: 0 | R41: 0 | S41: 0 | T41: 0 | U41: 0 | V41: 0 | W41: 0 | X41: 0 | Y41: 0 | Z41: 0 | AA41: 0 | AB41: 0 | AC41: 0 | AD41: 0 | AE41: 0 | AF41: 0 | AG41: 0 | AH41: 0 | AI41: 0 | AJ41: 0 | AK41: 0 | AL41: 0 | AM41: 0 | AN41: 0 | AO41: 0 | AP41: 0 | AQ41: 0 | AR41: 0 | AS41: 0 | AT41: 0 | AU41: 0 | AV41: 0 | AW41: 0 | AX41: 0 | AY41: 0
A42: Total number of laying hens certified | B42: =B16 -> 46135566 | C42: =B42*(1+$B$15) -> 46781464 | D42: =C42*(1+$B$15) -> 47436404 | E42: =D42*(1+$B$15) -> 48100514 | F42: =E42*(1+$B$15) -> 48773921 | G42: =F42*(1+$B$15) -> 49456756 | H42: =G42*(1+$B$15) -> 50149150 | I42: =H42*(1+$B$15) -> 50851239 | J42: =I42*(1+$B$15) -> 51563156 | ... AY42: =AX42*(1+$B$15) -> 91179172
A43: Total number of laying hens affected that have delayed AFE | B43: =B42*$B$21*$B$22*$B$37*(1-$B$23) -> 793626.84 | C43: =C42*$B$21*$B$22*$B$37*(1-$B$23) -> 804737.62 | D43: =D42*$B$21*$B$22*$B$37*(1-$B$23) -> 816003.94 | E43: =E42*$B$21*$B$22*$B$37*(1-$B$23) -> 827428 | F43: =F42*$B$21*$B$22*$B$37*(1-$B$23) -> 839011.99 | G43: =G42*$B$21*$B$22*$B$37*(1-$B$23) -> 850758.16 | H43: =H42*$B$21*$B$22*$B$37*(1-$B$23) -> 862668.77 | I43: =I42*$B$21*$B$22*$B$37*(1-$B$23) -> 874746.13 | ... AY43: =AY42*$B$21*$B$22*$B$37*(1-$B$23) -> 1568469.7
...

Sheet KAT Germany - 35%
A1: Inputs | B1: Expected | C1: Description | G1: Source
A2: Costs
A3: Fixed costs (Year 1) | B3: 130000 | C3: Held constant across all CEAs | G3: -
A4: Fixed costs (At scale) | B4: 280000 | C4: Held constant across all CEAs | G4: -
A5: Variable costs - Cost of working with certifiers | B5: =(89931*2/3)+AVERAGE(357000,498000,285000,435000,90554,213500,237043,300000) -> 361966.12 | C5: How much ALI has spent on their certifier campaigns over the last 18 months. Adjusted to reflect costs over 1 year. + How much OP has given to certifiers on average to get them to update their standards. | G5: https://animalcharityevaluators.org/charity-review/ciftlik-hayvanlarini-koruma-dernegi/#c2 https://animalcharityevaluators.org/charity-review/shrimp-welfare-project/#c2 https://animalcharityevaluators.org/charity-review/sinergia-animal/#c2 https://animalcharityevaluators.org/charity-review/the-humane-league/#c2 https://docs.google.com/document/d/1UHLMl1avIl7Sfxm-svVLbN_QCUdmDHzgsonIqKzN3bc/edit#heading=h.6783mx40fots
A6: Charity years operating | B6: 3 | C6: Assume charity gives up on KAT after 3 years if not successful If successful then runs at Year 1 levels to perform audits and undercover investigations of KAT farms | G6: -
A7: Years until implementation | B7: 3 | C7: KAT updates their certification standards every ~2 years and it was last updated in 2024. So the next round of updates would be published in 2026. This would only be 1 year after the new charity launches, so we assume that they don't impact standards until 2028 which is 3 years after the beginning of the charity. | G7: -
A9: Benefits
A10: Number of layers certified by KAT (2019) | B10: =82000000 -> 82000000 | C10: "In 2019, around 82 million hens in barn, free-range and organic production were registered" | G10: https://www.was-steht-auf-dem-ei.de/en/kat-association/index.php
A11: Of which free range or organic | B11: 0.28 | C11: 18% free range and 10% organic | G11: https://www.thuenen.de/en/thuenen-topics/long-term-policy-concepts/nationale-nutztierstrategie/the-egg-of-columbus#:~:text=Most%20eggs%20are%20now%20barn,floor%20or%20free%2Drange%20husbandry.
A12: Likelihood of affecting all hens | B12: 0.33 | C12: Best guess | G12: -
A13: Likelihood just free range or organic | B13: 0.67 | C13: Best guess | G13: -
A14: Estimated number of layers affected through KAT (2019) | B14: =B10*B13*B11+B10*B12 -> 42443200 | C14: Calculation | G14: -
A15: Growth rate of egg industry | B15: 0.014 | C15: "The Federal Statistical Office (Destatis) also reports that production increased by 1.4% compared with the previous year [2021-22]". Asusming growth rate holds. | G15: https://www.destatis.de/EN/Press/2023/03/PE23_104_413.html#:~:text=Increase%20in%20organic%20eggs%20of,compared%20with%20the%20previous%20year.
A16: Estimated number of layers affected through KAT (2025) | B16: =B14*(1+B15)^6 -> 46135566 | C16: Calculation of number of animals certified using growth rate of egg production in Germany | G16: -
A17: SADs attributed to KBF in aviaries currently | B17: 8.655 | C17: This is using Welfare Footprint's data including a prevalence of 30-100%. | G17: https://docs.google.com/spreadsheets/d/1DssnYoZKFSE3w_-E2PLuOImLUd56JK3JNoO6JHkmTPk/edit?gid=289821833#gid=289821833
A18: KBF prevelence before intervention | B18: 0.35
A19: KBF prevelence after intervention | B19: 0.25
A20: SADs averted per animal | B20: =B17-(B17/B18)*B19 -> 2.4728571 | C20: Calculation | G20: -
A21: Probability of success | B21: =AVERAGE(5/27,7/10,10/28,3/10,3/28,2/5,2/8,2/10,0.1,0.15,0.1) -> 0.25904281 | C21: We use an average of estimates here: 1. ALI's success rate 2. OpenPhil's success rate 3. Koushik's best guess of 10-15% 4. Vicky's best guess of 10% | G21: 1. ALI's success rate: https://docs.google.com/document/d/1cu4DKdrwczszdyVvTeC_jUgI3eXAF4Dk1ZXUSBsTYac/edit?tab=t.0#heading=h.ujzm6p1i0pzg 2. OP's success rate: https://docs.google.com/document/d/1cu4DKdrwczszdyVvTeC_jUgI3eXAF4Dk1ZXUSBsTYac/edit?tab=t.0#heading=h.6783mx40fots 3-4. Informed best guess
A22: Expected enforcement rate | B22: =AVERAGE(55%,70%) -> 0.625 | C22: Best guess enforcement rate of 55%-70% in the UK and Germany | G22: https://docs.google.com/document/d/1UHLMl1avIl7Sfxm-svVLbN_QCUdmDHzgsonIqKzN3bc/edit#bookmark=id.312v09ueelbp
A23: Farms that drop or swap certifier instead of implementing interventions to reduce KBF | B23: 0.15 | C23: Best guess | G23: -
A24: Discount rate (Costs) | B24: 0.04 | C24: Held constant across all CEAs | G24: -
A25: Baseline discount rate (Benefits) | B25: 0.014 | C25: Held constant across all CEAs | G25: -
A26: Annual chance that this would happen without our intervention | B26: 0.07 | C26: Best guess - I think this is quite unlikely as no one else is campaigning about KBF, but KAT standards seem quite strong so could see them adding this and there is at least one case study of a certifier having this requirement (GAP in the US) | G26: -
A27: Total discount rate (Benefits) | B27: =SUM(B25:B26) -> 0.084 | C27: Calculation - Sum of all discount rates | G27: -
A29: Potential negative externalities
A30: One potential intervention that could be implemented to reduce KBF is delaying the age at first egg (AFE) by 4-6 weeks to give the keel bone more time to fully ossify. It is unclear whether this will be good for hen welfare as it is likely that farmers will increase the length of the production cycle if delaying the age at first egg, which will mean that these animals will spend more time on farms. We assume that the production cycle will be lengthened by 4-6 weeks (the same amount of time that the age at first egg is delayed by).
A31: ="SADs per bird with "&B19&" prevalence of KBF" -> SADs per bird with 0.25 prevalence of KBF | B31: =(B17/B18)*B19 -> 6.1821429 | C31: 11.45472588 SADs per animal in aviary system, where 8.655792412 SADs are caused by 65% prevalence of KBF. If we reduce KBF prevalence to 25%, then total SADs will be ~6.12 SADs per animal
A32: Number of weeks farmed (without delayed AFE) | B32: 72 | C32: Laying hens are farmed for 72 weeks | G32: https://www.ciwf.org.uk/media/5235024/The-life-of-laying-hens.pdf
A33: Number of weeks AFE is delayed | B33: =AVERAGE(4,6) -> 5 | C33: AFE delayed by 4-6 weeks | G33: https://docs.google.com/document/d/1VRx3rD4-6A7Jwc3Inqn6LuAiCoPgxy2rKeocioIg5DU/edit
A34: % increase in production length | B34: =B33/B32 -> 0.069444444 | C34: Calculation: 5/72 | G34: -
A35: SADs per bird with 25% prevalence of KBF with delayed AFE | B35: =B31+(B31*B34) -> 6.6114583 | C35: Calculation: SADs per bird accounting for increased production length | G35: -
A36: Additional SADs caused per bird | B36: =B35-B31 -> 0.42931548 | C36: Calculation | G36: -
A37: Likelihood that farmers will implement this intervention | B37: =AVERAGE(5%,20%) -> 0.125 | C37: Best guess: 5-20% | G37: -
A39: Calculations
A40: Year | B40: 1 | C40: 2 | D40: 3 | E40: 4 | F40: 5 | G40: 6 | H40: 7 | I40: 8 | J40: 9 | K40: 10 | L40: 11 | M40: 12 | N40: 13 | O40: 14 | P40: 15 | Q40: 16 | R40: 17 | S40: 18 | T40: 19 | U40: 20 | V40: 21 | W40: 22 | X40: 23 | Y40: 24 | Z40: 25 | AA40: 26 | AB40: 27 | AC40: 28 | AD40: 29 | AE40: 30 | AF40: 31 | AG40: 32 | AH40: 33 | AI40: 34 | AJ40: 35 | AK40: 36 | AL40: 37 | AM40: 38 | AN40: 39 | AO40: 40 | AP40: 41 | AQ40: 42 | AR40: 43 | AS40: 44 | AT40: 45 | AU40: 46 | AV40: 47 | AW40: 48 | AX40: 49 | AY40: 50
A41: Total Costs | B41: =B3+B5 -> 491966.12 | C41: =$B$4+$B$5 -> 641966.12 | D41: =$B$4+$B$5 -> 641966.12 | E41: =$B$4*$B$21 -> 72531.987 | F41: =$B$4*$B$21 -> 72531.987 | G41: =$B$4*$B$21 -> 72531.987 | H41: =$B$4*$B$21 -> 72531.987 | I41: =$B$4*$B$21 -> 72531.987 | J41: =$B$4*$B$21 -> 72531.987 | K41: =$B$4*$B$21 -> 72531.987 | L41: =$B$4*$B$21 -> 72531.987 | ... P41: =$B$4*$B$21 -> 72531.987 | Q41: 0 | R41: 0 | S41: 0 | T41: 0 | U41: 0 | V41: 0 | W41: 0 | X41: 0 | Y41: 0 | Z41: 0 | AA41: 0 | AB41: 0 | AC41: 0 | AD41: 0 | AE41: 0 | AF41: 0 | AG41: 0 | AH41: 0 | AI41: 0 | AJ41: 0 | AK41: 0 | AL41: 0 | AM41: 0 | AN41: 0 | AO41: 0 | AP41: 0 | AQ41: 0 | AR41: 0 | AS41: 0 | AT41: 0 | AU41: 0 | AV41: 0 | AW41: 0 | AX41: 0 | AY41: 0
A42: Total number of laying hens certified | B42: =B16 -> 46135566 | C42: =B42*(1+$B$15) -> 46781464 | D42: =C42*(1+$B$15) -> 47436404 | E42: =D42*(1+$B$15) -> 48100514 | F42: =E42*(1+$B$15) -> 48773921 | G42: =F42*(1+$B$15) -> 49456756 | H42: =G42*(1+$B$15) -> 50149150 | I42: =H42*(1+$B$15) -> 50851239 | J42: =I42*(1+$B$15) -> 51563156 | ... AY42: =AX42*(1+$B$15) -> 91179172
A43: Total number of laying hens affected that have delayed AFE | B43: =B42*$B$21*$B$22*$B$37*(1-$B$23) -> 793626.84 | C43: =C42*$B$21*$B$22*$B$37*(1-$B$23) -> 804737.62 | D43: =D42*$B$21*$B$22*$B$37*(1-$B$23) -> 816003.94 | E43: =E42*$B$21*$B$22*$B$37*(1-$B$23) -> 827428 | F43: =F42*$B$21*$B$22*$B$37*(1-$B$23) -> 839011.99 | G43: =G42*$B$21*$B$22*$B$37*(1-$B$23) -> 850758.16 | H43: =H42*$B$21*$B$22*$B$37*(1-$B$23) -> 862668.77 | I43: =I42*$B$21*$B$22*$B$37*(1-$B$23) -> 874746.13 | ... AY43: =AY42*$B$21*$B$22*$B$37*(1-$B$23) -> 1568469.7
...

Sheet RSPCA UK
A1: Inputs | B1: Expected | C1: Description | G1: Source
A2: Costs
A3: Fixed costs (Year 1) | B3: 130000 | C3: Held constant across all CEAs | G3: -
A4: Fixed costs (At scale) | B4: 280000 | C4: Held constant across all CEAs | G4: -
A5: Variable costs - Cost of working with certifiers | B5: =(89931*2/3)+AVERAGE(357000,498000,285000,435000,90554,213500,237043,300000) -> 361966.12 | C5: How much ALI has spent on their certifier campaigns over the last 18 months. Adjusted to reflect costs over 1 year. + How much OP has given to certifiers on average to get them to update their standards. | G5: https://animalcharityevaluators.org/charity-review/ciftlik-hayvanlarini-koruma-dernegi/#c2 https://animalcharityevaluators.org/charity-review/shrimp-welfare-project/#c2 https://animalcharityevaluators.org/charity-review/sinergia-animal/#c2 https://animalcharityevaluators.org/charity-review/the-humane-league/#c2 https://docs.google.com/document/d/1UHLMl1avIl7Sfxm-svVLbN_QCUdmDHzgsonIqKzN3bc/edit#heading=h.6783mx40fots
A6: Charity years operating | B6: 3 | C6: Assume charity gives up on KAT after 3 years if not successful If successful then runs at Year 1 levels to perform audits and undercover investigations of KAT farms | G6: -
A7: Years until implementation | B7: 3 | C7: KAT updates their certification standards every ~2 years and it was last updated in 2024. So the next round of updates would be published in 2026. This would only be 1 year after the new charity launches, so we assume that they don't impact standards until 2028 which is 3 years after the beginning of the charity. | G7: -
A9: Benefits
A10: Number of layers farmed in the UK | B10: =40.5*1000000 -> 40500000 | C10: "Every year in the UK, we consume over 13 billion eggs. The majority of these come from the 40.5 million egg-laying hens farmed in the UK each year." | G10: https://www.rspcaassured.org.uk/farmed-animal-welfare/egg-laying-hens/
A11: % of layers certified by RSPCA | B11: 0.51 | C11: "51% of laying hens in the UK are RSPCA Assured" (All RSPCA assured eggs are cage-free) | G11: https://www.rspcaassured.org.uk/media/plndbb1e/rspcaass_a5_annualreview22_v13d.pdf
A12: Of which free range or organic | B12: 0.66 | C12: 62% free range and 4% organic (based on Q3 2022 data) | G12: https://www.gov.uk/government/statistics/historical-statistic-notices-on-uk-egg-production-and-prices-2022/united-kingdom-egg-statistics-quarter-3-2022
A13: Likelihood of affecting all hens | B13: 0.33 | C13: Best guess | G13: -
A14: Likelihood just free range or organic | B14: 0.67 | C14: Best guess | G14: -
A15: Estimated number of layers affected through RSPCA | B15: =B10*B11*B14*B12+B10*B11*B13 -> 15949791 | C15: Calculation | G15: -
A16: Growth rate of egg industry | B16: -0.04 | C16: Based on growth rate of sales volume for eggs in the UK | G16: https://www.egginfo.co.uk/egg-facts-and-figures/industry-information/data
A17: SADs attributed to KBF in aviaries currently | B17: 8.655 | C17: This is using Welfare Footprint's data including a prevalence of 30-100%. | G17: https://docs.google.com/spreadsheets/d/1DssnYoZKFSE3w_-E2PLuOImLUd56JK3JNoO6JHkmTPk/edit?gid=289821833#gid=289821833
A18: KBF prevelence before intervention | B18: 0.65 | C18: KBF prevalence is 30-100% | G18: https://cp.pain-track.org/hens
A19: KBF prevelence after intervention | B19: 0.4 | C19: Best guess on what enforcement will actually be with a target of 25% | G19: -
A20: SADs averted per animal | B20: =B17-(B17/B18)*B19 -> 3.3288462 | C20: Calculation | G20: -
A21: Probability of success | B21: =AVERAGE(5/27,7/10,10/28,3/10,3/28,2/5,2/8,2/10,0.1,0.15,0.1) -> 0.25904281 | C21: We use an average of estimates here: 1. ALI's success rate 2. OpenPhil's success rate 3. Koushik's best guess of 10-15% 4. Vicky's best guess of 10% | G21: 1. ALI's success rate: https://docs.google.com/document/d/1cu4DKdrwczszdyVvTeC_jUgI3eXAF4Dk1ZXUSBsTYac/edit?tab=t.0#heading=h.ujzm6p1i0pzg 2. OP's success rate: https://docs.google.com/document/d/1cu4DKdrwczszdyVvTeC_jUgI3eXAF4Dk1ZXUSBsTYac/edit?tab=t.0#heading=h.6783mx40fots 3-4. Informed best guess
A22: Expected enforcement rate | B22: =AVERAGE(55%,70%) -> 0.625 | C22: Best guess enforcement rate of 55%-70% in the UK and Germany | G22: https://docs.google.com/document/d/1UHLMl1avIl7Sfxm-svVLbN_QCUdmDHzgsonIqKzN3bc/edit#bookmark=id.312v09ueelbp
A23: Farms that drop or swap certifier instead of implementing interventions to reduce KBF | B23: 0.15 | C23: Best guess | G23: -
A24: Discount rate (Costs) | B24: 0.04 | C24: Held constant across all CEAs | G24: -
A25: Baseline discount rate (Benefits) | B25: 0.014 | C25: Held constant across all CEAs | G25: -
A26: Annual chance that this would happen without our intervention | B26: 0.015 | C26: Best guess - I think this is quite unlikely as no one else is campaigning about KBF, and expect RSPCA standards to be less good than KAT | G26: -
A27: Total discount rate (Benefits) | B27: =SUM(B25:B26) -> 0.029 | C27: Calculation - Sum of all discount rates | G27: -
A29: Potential negative externalities
A30: One potential intervention that could be implemented to reduce KBF is delaying the age at first egg (AFE) by 4-6 weeks to give the keel bone more time to fully ossify. It is unclear whether this will be good for hen welfare as it is likely that farmers will increase the length of the production cycle if delaying the age at first egg, which will mean that these animals will spend more time on farms. We assume that the production cycle will be lengthened by 4-6 weeks (the same amount of time that the age at first egg is delayed by).
A31: ="SADs per bird with "&B19&" prevalence of KBF" -> SADs per bird with 0.4 prevalence of KBF | B31: =(B17/B18)*B19 -> 5.3261538 | C31: 11.45472588 SADs per animal in aviary system, where 8.655792412 SADs are caused by 65% prevalence of KBF. If we reduce KBF prevalence to 25%, then total SADs will be ~6.12 SADs per animal
A32: Number of weeks farmed (without delayed AFE) | B32: 72 | C32: Laying hens are farmed for 72 weeks | G32: https://www.ciwf.org.uk/media/5235024/The-life-of-laying-hens.pdf
A33: Number of weeks AFE is delayed | B33: =AVERAGE(4,6) -> 5 | C33: AFE delayed by 4-6 weeks | G33: https://docs.google.com/document/d/1VRx3rD4-6A7Jwc3Inqn6LuAiCoPgxy2rKeocioIg5DU/edit
A34: % increase in production length | B34: =B33/B32 -> 0.069444444 | C34: Calculation: 5/72 | G34: -
A35: SADs per bird with 25% prevalence of KBF with delayed AFE | B35: =B31+(B31*B34) -> 5.6960256 | C35: Calculation: SADs per bird accounting for increased production length | G35: -
A36: Additional SADs caused per bird | B36: =B35-B31 -> 0.36987179 | C36: Calculation | G36: -
A37: Likelihood that farmers will implement this intervention | B37: =AVERAGE(5%,20%) -> 0.125 | C37: Best guess: 5-20% | G37: -
A39: Calculations
A40: Year | B40: 1 | C40: 2 | D40: 3 | E40: 4 | F40: 5 | G40: 6 | H40: 7 | I40: 8 | J40: 9 | K40: 10 | L40: 11 | M40: 12 | N40: 13 | O40: 14 | P40: 15 | Q40: 16 | R40: 17 | S40: 18 | T40: 19 | U40: 20 | V40: 21 | W40: 22 | X40: 23 | Y40: 24 | Z40: 25 | AA40: 26 | AB40: 27 | AC40: 28 | AD40: 29 | AE40: 30 | AF40: 31 | AG40: 32 | AH40: 33 | AI40: 34 | AJ40: 35 | AK40: 36 | AL40: 37 | AM40: 38 | AN40: 39 | AO40: 40 | AP40: 41 | AQ40: 42 | AR40: 43 | AS40: 44 | AT40: 45 | AU40: 46 | AV40: 47 | AW40: 48 | AX40: 49 | AY40: 50
A41: Total Costs | B41: =B3+B5 -> 491966.12 | C41: =$B$4+$B$5 -> 641966.12 | D41: =$B$4+$B$5 -> 641966.12 | E41: =$B$4*$B$21 -> 72531.987 | F41: =$B$4*$B$21 -> 72531.987 | G41: =$B$4*$B$21 -> 72531.987 | H41: =$B$4*$B$21 -> 72531.987 | I41: =$B$4*$B$21 -> 72531.987 | J41: =$B$4*$B$21 -> 72531.987 | K41: =$B$4*$B$21 -> 72531.987 | L41: =$B$4*$B$21 -> 72531.987 | ... P41: =$B$4*$B$21 -> 72531.987 | Q41: 0 | R41: 0 | S41: 0 | T41: 0 | U41: 0 | V41: 0 | W41: 0 | X41: 0 | Y41: 0 | Z41: 0 | AA41: 0 | AB41: 0 | AC41: 0 | AD41: 0 | AE41: 0 | AF41: 0 | AG41: 0 | AH41: 0 | AI41: 0 | AJ41: 0 | AK41: 0 | AL41: 0 | AM41: 0 | AN41: 0 | AO41: 0 | AP41: 0 | AQ41: 0 | AR41: 0 | AS41: 0 | AT41: 0 | AU41: 0 | AV41: 0 | AW41: 0 | AX41: 0 | AY41: 0
A42: Total number of laying hens certified | B42: =B15 -> 15949791 | C42: =B42*(1+$B$16) -> 15311799 | D42: =C42*(1+$B$16) -> 14699327 | E42: =D42*(1+$B$16) -> 14111354 | F42: =E42*(1+$B$16) -> 13546900 | G42: =F42*(1+$B$16) -> 13005024 | H42: =G42*(1+$B$16) -> 12484823 | I42: =H42*(1+$B$16) -> 11985430 | J42: =I42*(1+$B$16) -> 11506013 | ... AY42: =AX42*(1+$B$16) -> 2157970.1
A43: Total number of laying hens affected that have delayed AFE | B43: =B42*$B$21*$B$22*$B$37*(1-$B$23) -> 274369.29 | C43: =C42*$B$21*$B$22*$B$37*(1-$B$23) -> 263394.51 | D43: =D42*$B$21*$B$22*$B$37*(1-$B$23) -> 252858.73 | E43: =E42*$B$21*$B$22*$B$37*(1-$B$23) -> 242744.38 | F43: =F42*$B$21*$B$22*$B$37*(1-$B$23) -> 233034.61 | G43: =G42*$B$21*$B$22*$B$37*(1-$B$23) -> 223713.23 | H43: =H42*$B$21*$B$22*$B$37*(1-$B$23) -> 214764.7 | I43: =I42*$B$21*$B$22*$B$37*(1-$B$23) -> 206174.11 | ... AY43: =AY42*$B$21*$B$22*$B$37*(1-$B$23) -> 37121.534
...

Sheet UEP USA
A1: Inputs | B1: Expected | C1: Description | G1: Source
A2: Costs
A3: Fixed costs (Year 1) | B3: 130000 | C3: Held constant across all CEAs | G3: -
A4: Fixed costs (At scale) | B4: 280000 | C4: Held constant across all CEAs | G4: -
A5: Variable costs - Cost of working with certifiers | B5: =(89931*2/3)+AVERAGE(357000,498000,285000,435000,90554,213500,237043,300000) -> 361966.12 | C5: How much ALI has spent on their certifier campaigns over the last 18 months. Adjusted to reflect costs over 1 year. + How much OP has given to certifiers on average to get them to update their standards. | G5: https://animalcharityevaluators.org/charity-review/ciftlik-hayvanlarini-koruma-dernegi/#c2 https://animalcharityevaluators.org/charity-review/shrimp-welfare-project/#c2 https://animalcharityevaluators.org/charity-review/sinergia-animal/#c2 https://animalcharityevaluators.org/charity-review/the-humane-league/#c2 https://docs.google.com/document/d/1UHLMl1avIl7Sfxm-svVLbN_QCUdmDHzgsonIqKzN3bc/edit#heading=h.6783mx40fots
A6: Charity years operating | B6: 3 | C6: Assume charity gives up on KAT after 3 years if not successful If successful then runs at Year 1 levels to perform audits and undercover investigations of KAT farms | G6: -
A7: Years until implementation | B7: 3 | C7: KAT updates their certification standards every ~2 years and it was last updated in 2024. So the next round of updates would be published in 2026. This would only be 1 year after the new charity launches, so we assume that they don't impact standards until 2028 which is 3 years after the beginning of the charity. | G7: -
A9: Benefits
A10: Number of layers farmed in the US (2022) | B10: 308000000 | C10: "The U.S. had 308 million commercial laying hens at the end of 2022" | G10: https://unitedegg.com/facts-stats/
A11: % cage-free in the US | B11: 0.39 | C11: "39% of American hens... are now cage-free" | G11: https://farmanimalwelfare.substack.com/p/a-year-of-wins-for-farmed-animals
A12: % of eggs certified by UEP | B12: 0.9 | C12: "More than 90 percent of eggs produced in the U.S. come from farms that voluntarily participate in UEP Certified, choosing to open their farms to independent auditors." | G12: https://www.uepcertified.com/#:~:text=UEP%20Certified%20established%20guidelines%20for,their%20farms%20to%20independent%20auditors.
A13: Of which free range or organic | B13: 0.108 | C13: 5% free range and 5.8% organic | G13: https://unitedegg.com/facts-stats/ https://www.wattagnet.com/egg/article/15676848/questions-answered-about-the-us-freerange-egg-market
A14: Likelihood of affecting all hens | B14: 0.33 | C14: Best guess | G14: -
A15: Likelihood just free range or organic | B15: 0.67 | C15: Best guess | G15: -
A16: Number of layers affected through UEP (2022) | B16: =B10*B11*B12*B15*B13+B10*B11*B12*B14 -> 43498335 | C16: Calculation | G16: -
A17: Growth rate of egg industry | B17: -0.03 | C17: "U.S. table egg production totaled 92.6 billion in 2022, a 3% decrease from 2021" | G17: https://unitedegg.com/facts-stats/
A18: Number of layers affected through UEP (2025) | B18: =B16*(1+B17)^3 -> 39699756 | C18: Calculation of number of animals certified using growth rate of egg production in Germany | G18: -
A19: SADs attributed to KBF in aviaries currently | B19: 8.655 | C19: This is using Welfare Footprint's data including a prevalence of 30-100%. | G19: https://docs.google.com/spreadsheets/d/1DssnYoZKFSE3w_-E2PLuOImLUd56JK3JNoO6JHkmTPk/edit?gid=289821833#gid=289821833
A20: KBF prevelence before intervention | B20: 0.65 | C20: KBF prevalence is 30-100% | G20: https://cp.pain-track.org/hens
A21: KBF prevelence after intervention | B21: 0.4 | C21: Best guess on what enforcement will actually be with a target of 25% | G21: -
A22: SADs averted per animal | B22: =B19-(B19/B20)*B21 -> 3.3288462 | C22: Calculation | G22: -
A23: Probability of success | B23: =AVERAGE(5/27,7/10,10/28,3/10,3/28,2/5,2/8,2/10,0.1,0.15,0.1) -> 0.25904281 | C23: We use an average of estimates here: 1. ALI's success rate 2. OpenPhil's success rate 3. Koushik's best guess of 10-15% 4. Vicky's best guess of 10% | G23: 1. ALI's success rate: https://docs.google.com/document/d/1cu4DKdrwczszdyVvTeC_jUgI3eXAF4Dk1ZXUSBsTYac/edit?tab=t.0#heading=h.ujzm6p1i0pzg 2. OP's success rate: https://docs.google.com/document/d/1cu4DKdrwczszdyVvTeC_jUgI3eXAF4Dk1ZXUSBsTYac/edit?tab=t.0#heading=h.6783mx40fots 3-4. Informed best guess
A24: Expected enforcement rate | B24: =AVERAGE(45%,55%) -> 0.5 | C24: Best guess enforcement rate of 45-55% in the US | G24: https://docs.google.com/document/d/1UHLMl1avIl7Sfxm-svVLbN_QCUdmDHzgsonIqKzN3bc/edit#bookmark=id.312v09ueelbp
A25: Farms that drop or swap certifier instead of implementing interventions to reduce KBF | B25: 0.15 | C25: Best guess | G25: -
A26: Discount rate (Costs) | B26: 0.04 | C26: Held constant across all CEAs | G26: -
A27: Baseline discount rate (Benefits) | B27: 0.014 | C27: Held constant across all CEAs | G27: -
A28: Annual chance that this would happen without our intervention | B28: 0.01 | C28: Best guess - I think this is quite unlikely as no one else is campaigning about KBF, and expect UEP standards to be less good than KAT and RSPCA in general | G28: -
A29: Total discount rate (Benefits) | B29: =SUM(B27:B28) -> 0.024 | C29: Calculation - Sum of all discount rates | G29: -
A31: Potential negative externalities
A32: One potential intervention that could be implemented to reduce KBF is delaying the age at first egg (AFE) by 4-6 weeks to give the keel bone more time to fully ossify. It is unclear whether this will be good for hen welfare as it is likely that farmers will increase the length of the production cycle if delaying the age at first egg, which will mean that these animals will spend more time on farms. We assume that the production cycle will be lengthened by 4-6 weeks (the same amount of time that the age at first egg is delayed by).
A33: ="SADs per bird with "&B21&" prevalence of KBF" -> SADs per bird with 0.4 prevalence of KBF | B33: =(B19/B20)*B21 -> 5.3261538 | C33: 11.45472588 SADs per animal in aviary system, where 8.655792412 SADs are caused by 65% prevalence of KBF. If we reduce KBF prevalence to 25%, then total SADs will be ~6.12 SADs per animal
A34: Number of weeks farmed (without delayed AFE) | B34: 72 | C34: Laying hens are farmed for 72 weeks | G34: https://www.ciwf.org.uk/media/5235024/The-life-of-laying-hens.pdf
A35: Number of weeks AFE is delayed | B35: =AVERAGE(4,6) -> 5 | C35: AFE delayed by 4-6 weeks | G35: https://docs.google.com/document/d/1VRx3rD4-6A7Jwc3Inqn6LuAiCoPgxy2rKeocioIg5DU/edit
A36: % increase in production length | B36: =B35/B34 -> 0.069444444 | C36: Calculation: 5/72 | G36: -
A37: SADs per bird with 25% prevalence of KBF with delayed AFE | B37: =B33+(B33*B36) -> 5.6960256 | C37: Calculation: SADs per bird accounting for increased production length | G37: -
A38: Additional SADs caused per bird | B38: =B37-B33 -> 0.36987179 | C38: Calculation | G38: -
A39: Likelihood that farmers will implement this intervention | B39: =AVERAGE(5%,20%) -> 0.125 | C39: Best guess: 5-20% | G39: -
A41: Calculations
A42: Year | B42: 1 | C42: 2 | D42: 3 | E42: 4 | F42: 5 | G42: 6 | H42: 7 | I42: 8 | J42: 9 | K42: 10 | L42: 11 | M42: 12 | N42: 13 | O42: 14 | P42: 15 | Q42: 16 | R42: 17 | S42: 18 | T42: 19 | U42: 20 | V42: 21 | W42: 22 | X42: 23 | Y42: 24 | Z42: 25 | AA42: 26 | AB42: 27 | AC42: 28 | AD42: 29 | AE42: 30 | AF42: 31 | AG42: 32 | AH42: 33 | AI42: 34 | AJ42: 35 | AK42: 36 | AL42: 37 | AM42: 38 | AN42: 39 | AO42: 40 | AP42: 41 | AQ42: 42 | AR42: 43 | AS42: 44 | AT42: 45 | AU42: 46 | AV42: 47 | AW42: 48 | AX42: 49 | AY42: 50
A43: Total Costs | B43: =B3+B5 -> 491966.12 | C43: =$B$4+$B$5 -> 641966.12 | D43: =$B$4+$B$5 -> 641966.12 | E43: =$B$4*$B$23 -> 72531.987 | F43: =$B$4*$B$23 -> 72531.987 | G43: =$B$4*$B$23 -> 72531.987 | H43: =$B$4*$B$23 -> 72531.987 | I43: =$B$4*$B$23 -> 72531.987 | J43: =$B$4*$B$23 -> 72531.987 | K43: =$B$4*$B$23 -> 72531.987 | L43: =$B$4*$B$23 -> 72531.987 | ... P43: =$B$4*$B$23 -> 72531.987 | Q43: 0 | R43: 0 | S43: 0 | T43: 0 | U43: 0 | V43: 0 | W43: 0 | X43: 0 | Y43: 0 | Z43: 0 | AA43: 0 | AB43: 0 | AC43: 0 | AD43: 0 | AE43: 0 | AF43: 0 | AG43: 0 | AH43: 0 | AI43: 0 | AJ43: 0 | AK43: 0 | AL43: 0 | AM43: 0 | AN43: 0 | AO43: 0 | AP43: 0 | AQ43: 0 | AR43: 0 | AS43: 0 | AT43: 0 | AU43: 0 | AV43: 0 | AW43: 0 | AX43: 0 | AY43: 0
...
