Workbook
Name MigrantsAtScale: #REF!
Name DiscountRate: #REF!
Name ConsumptionDoublingsMigrant: #REF!
Name CostScale: #REF!
Name AudienceSize: #REF!
Name CostOfMigrating: #REF!
Name MigrantsAtScale: #REF!
Name TimePrep: #REF!
Name TotalDoublings: #REF!
Name TimeToScale: #REF!
Name TotalAirtimeCost: #REF!
Name CostOfMigrating: #REF!
Name TimeToFail: #REF!
Name ProbSuccess: 'Main model'!$B$116
Name AnnualRiseInIncome: #REF!
Name CostY1: #REF!
Name TotalProductionCost: #REF!
Name CostY1: #REF!
Name TimeToScale: #REF!
Name TotalProductionCost: #REF!
Name ConsumptionIncreaseMigrant: #REF!
Name TimeToScale: #REF!
Name ConsumptionDoublingsMigrant: #REF!
Name Scale: #REF!
Name DiscountRate: #REF!
Name Year: #REF!
Name CampaignMonths: #REF!
Name CostScale: #REF!
Name NumberOfStations: #REF!
Name AudienceSize: #REF!
Name CostScale: #REF!
Name Scale: #REF!
Name ConsumptionIncreaseMigrant: #REF!
Name TimeToFail: 'OLD 2023 CEA'!$B$12
Name TotalDALYs: #REF!
Name TotalAirtimeCost: #REF!
Name AudienceSize: #REF!
Name Year: #REF!
Name ConsumptionDoublingsMigrant: #REF!
Name TotalDALYs: #REF!
Name Year: #REF!
Name NumberOfStations: #REF!
Name ProbSuccess: 'OLD 2023 CEA'!$B$11
Name ProbCounterfactual: #REF!
Name TimeToFail: 'Main model'!$B$117
Name TotalProductionCost: #REF!
Name CampaignMonths: #REF!
Name AnnualRiseInIncome: #REF!
Name TotalDoublings: #REF!
Name ProbSuccess: #REF!
Name TotalAirtimeCost: #REF!
Name MigrantsAtScale: #REF!
Name NumberOfStations: #REF!
Name Scale: #REF!
Name TotalDoublings: #REF!
Name ConsumptionIncreaseMigrant: #REF!
Name CostOfMigrating: #REF!
Name TotalDALYs: #REF!
Name ProbCounterfactual: #REF!
Name AnnualRiseInIncome: #REF!

Sheet Key
B1: Welcome to our CEA...
A3: Introduction – what this is and what this is not
B4: Our CEAs are primarily designed to support the AIM team to make decisions between ideas. This means we prioritise our CEAs being comparable to each other. This is not always the same as prioritising accuracy. For example if one CEA goes into much more depth than others, that would be a bad thing for our overall decision making. Also we use similar figures across CEAs justified on grounds of being the default figure to use across CEAs. You might even spot some strange uses of units like "DALY equivalents" where monetary benefits are converted to health benefits or visa versa. That said, there should not be errors or mistakes in our CEAs. These do occasionally crop up. If you do find an error or just want to challenge our modelling assumptions we are open to feedback. Feel free to reach out to the us via the form at: https://www.charityentrepreneurship.com/contact
A7: Key to colours used in the CEA
C8: Input
C9: Subjective judgement
C10: Variable imported input from another tab/sheet (mostly used when data input varies based on country chosen)
C11: Calculation
A14: Guide to the tabs
B15: Tab name | C15: Description
B16: Main CEA | C16: The main tab of this CEA where most inputs live and calculations happen
B17: Country data | C17: Occasionally we want to model multiple countries at once. This tab contains the data that varies based on the country being modelled.
B18: Uncertainty | C18: Sometimes we want to model the uncertainty. This tab runs a simple Monte Carlo uncertainty moddelling script.
B19: Data: _____ | C19: These tabs contain various data sets that may be used in modelling. They may or may not have been used in this CEA.
B20: Calc: _____ | C20: Sometimes a CEA author will want to do some background data calculations in another tab so might add a tab like this
A23: Reading the CEA
C25: Researcher's best guess expected value estimate for the input at hand ↓ | D25: The unit of measurement for the estimate ↓ | E25: An explanation of our thinking in relation to the input ↓ | F25: Link or links to the key sources data is taken from ↓ | I25: ◄ | J25: Hidden columns may be used for uncertainty ▶ modelling ↓
C26: Value | D26: Units | E26: Description | F26: Source | G26: Reviewer notes | H26: Replies | I26: → | J26: ← Hidden optional uncertinaty modelling
B28: Description of intervention
B29: [Fill out description here] | E29: ← We normally begin with a description of the intervention
B30: Geographic focus: | C30: [country / region] | E30: ← If this cell is highlighted orange you can use it as a dropdown to decide what country you want to see the results for
B31: Beneficiary – this CEA models the costs effect and reach per: | C31: [person]
B32: Impact – this CEA models the impact in terms of: | C32: [DALY] | E32: ← The CEA will normally measure impact in the amount of this per $, in this example it would be [DALY]/$
B34: Costs of intervention | E34: ← The CEA is modular and broken down into sections for easy reading and to allow comparison between different CEAs
B36: 1. FIXED COSTS | E36: ← Each section is comprised of various sub-sections like this
B37: [Subheading]
B38: Fixed costs in [first] year [Suggest: $130,000] | C38: 130000 | D38: $ | E38: ← Some cells have notes like this ◥. They were to help the CEA authors, mostly you can ignore them
B39: Ongoing annual fixed costs when at scale [Suggest: $280,000] | C39: 280000 | D39: $
B40: Additional upfront fixed costs before reaching scale [Normally: $0] | C40: 0 | D40: $
B42: TOTAL CHARITY COSTS WHEN AT SCALE | E42: ← Sections end with a subsection in bold that calculates the results of that section
B43: Total fixed costs when at scale | C43: =C39 -> 280000 | D43: $
B45: Effects per [beneficiary]
B47: Reach of intervention
B49: Tractability & counterfactuals
B51: Timing to scale and discounting | E51: ← In this section the CEA author defines the discount rates, the changing effects over time, And the time taken to scale up the costs and the impact.
E52: The actual calculations are hard to follow so are often hidden, but they should all be replicated in a more transparent easy to follow way in the timeline check below
B54: Results
B56: Timeline check | E56: ← The timeline shows the cost and the impact each year. It does the same calculations as the "Timing to scale and discounting" section
B58: ** Result 4 – cost effectiveness FINAL RESULT ** | E58: ← We have a range of different results. This helps support decision making (we can manage multiple numbers) and allow us to understand and compare our models
B59: R4: Cost effectiveness per year ($/Impact) | C59: 100 | D59: $/[DALY]
...

Sheet Main model
B1: Value | C1: Units | D1: Description | E1: Source
A2: Description of intervention
A3: This is a policy/advocacy intervention that targets ULAB recycling in Thailand and scaling to two other similar countries. The goal would be the push some of the informal recycling market share into the formal recycling sector. We are moddeling some general policy improvements here, based on an estimate of the effect of BLL.
A4: Geographic focus: | B4: Thailand
A5: Beneficiary – this CEA models the costs effect and reach per: | B5: country
A6: Impact – this CEA models the impact in terms of: | B6: DALY equivelents
A9: Costs of intervention
A11: 1. FIXED COSTS
A12: Fixed costs in first year | B12: 130000 | C12: $ | D12: Estimate (from Joey) for 90% confidence interval for CE seed grant is $100k to $190k
A13: Ongoing annual fixed costs when at scale - base | B13: 280000 | C13: $ | D13: Based on estimate from Joey
A14: Total ongoing annual fixed costs when at scale | B14: =B13 -> 280000 | C14: $
A16: 2. VARIABLE CHARITY COSTS
A17: ="Median salary in "&B4 -> Median salary in Thailand | B17: {=INDEX('Median salaries'!G:G,MATCH(B4,'Median salaries'!A:A,0))} -> 14366.019 | C17: $
A18: Policy costs | B18: =50000 + 5*B17 -> 121830.1 | C18: $ | D18: Policy costs: We use $50,000 + 5 * median local salary
A19: Cost per additional country | B19: =B18 -> 121830.1 | C19: $/country | D19: ="Unsure what those other countries are; assuming the same costs as "&B4 -> Unsure what those other countries are; assuming the same costs as Thailand
A21: TOTAL CHARITY COSTS WHEN AT SCALE
A22: Total costs when at scale | B22: =B14 + B19*B103 -> 645490.29 | D22: For display; not actually used in any formula
A24: ="Effects per "&$B$5 -> Effects per country
A25: Key assumptions / data
A26: One year of doubled consumption to DALYs [fixed] | B26: =1/2.5 -> 0.4 | C26: ratio
A27: Discount rate for health impacts | B27: 0.014 | C27: % discounted
A28: Discount rate for consumption impacts | B28: 0.04 | C28: % discounted
A29: Population per country | B29: 71700000 | C29: people | E29: https://ourworldindata.org/grapher/population?time=latest&country=~THA&focus=~THA
A30: Births per country per year | B30: =8.24/1000*B29 -> 590808 | C30: births | E30: https://ourworldindata.org/grapher/crude-birth-rate
A32: Reduction in BLLs due to the intervention
A33: Percentage of burden attributable to informal ULAB recycling
A34: Directly due to ULAB recycling | B34: 0.15 | C34: % | D34: Best guess based on tab on 'overall GBD ULAB recycling' and upcoming paper from Forsyth which states that ULABs are responsible for 30% of lead poisoning in Dhaka, Bangladesh. Bret Ericson thought it is somewhere around 10%, Hugo thought 20%.
A35: Total burden attributable to cookware | B35: 0.25 | C35: % | D35: Best guess
A36: % of cookware contamination resulting from ULAB recycling. | B36: 0.1 | C36: % | D36: Intuition. Some experts told us that in Mexico, both formal and informal recyclers sell lead (dust) to artisinal cookware makers.
A37: Additional contamination via grown crops near ULAB recycling plants/informal recyclers | B37: 0.02 | C37: % | D37: One route is contamination via vegetables, see paper: https://www.sciencedirect.com/science/article/abs/pii/S0013935123012215
A38: Percentage attributable to formal and informal ULAB recycling | B38: =B34 + B35*B36 + B37 -> 0.195 | C38: %
A40: Decrease in burden when substantial regulations are implemented
A41: Estimating the effect of the policies in Brazil | D41: We base our calculation on the effect estimated for Brazil
A42: Burden due to informal recycling in Brazil before improved regulation | B42: 0.8 | C42: % | D42: Estimate, based on assuming that the formal sector emits 5x less lead (per battery) than the informal sector, which seems plausible (see Table 1 in the report)
A43: Size of informal sector in Brazil before improved regulation | B43: 0.45 | C43: % | D43: Carlos Zaim mentioned 40-45% , other sources claim 'the majority', so i went for 45%. Also, the blogpost mention some rough numbers, but that must have come from Carlos as well- https://leadbatteries.substack.com/p/how-brazil-solved-its-lead-acid-battery
A44: Size of informal sector in Brazil after regulation | B44: 0.1 | C44: % | D44: IBER has 75% of market in 2022, could expect this to have increased
A45: Decrease of size of informal recycling due to regulations | B45: =1-B44/B43 -> 0.77777778 | C45: % | D45: Mark stevenson made a judgementcall, that a decrease of 50% would happen if taxes are cut in India Hugo: This number should be at least 50%. Best info he got on this was a quote: "most was informal before", Now 75% of the battery recycling is going via IBER. Also, Pure Earth states about 80%, see here: https://www.google.com/url?q=https://e360.yale.edu/features/getting-the-lead-out-why-battery-recycling-is-a-global-health-hazard%23:~:text%3DFuller%2520at%2520Pure%2520Earth%2520says,%252C%25E2%2580%259D%2520mainly%2520through%2520economic%2520incentives&sa=D&source=editors&ust=1733491202096199&usg=AOvVaw0aomdHgPlN28-Xc1QU9qWz
A46: Decrease of total ULAB burden due to regulations | B46: =B42*B45 -> 0.62222222 | C46: %
A48: Discounts for moving to a new context
A49: Improved policies not as effective as in Brazil, e.g. different response as there are different incentives, unknown | B49: 0.35 | C49: % reduction | D49: Intuition, there might be many reasons to think that the policy is not as effective. We err on the side that things worked out quite well for Brazil, e.g. because only some of the policies may be implemented
...

Sheet  Top Down - GBD
A1: I think this approach is the best/most correct, and could do with improvements. Results are surprisingly simliar as the LeRA type top down approach
C2: Bangladesh | D2: Argentina | E2: Thailand | F2: Units | G2: Description | H2: Source | I2: Review
A3: Total DALY burden Lead exposure in 2021 in country | C3: 927511 | D3: 78594 | E3: 131213 | F3: DALY | H3: https://ourworldindata.org/grapher/disease-burden-lead?tab=table
A4: Average increase/decrease, last 10 years ( 2011 - 2021) | C4: 0.21 | D4: =-6% -> -0.06 | E4: 0.14 | F4: % | G4: Based on trajectory since 1990 | H4: https://ourworldindata.org/grapher/disease-burden-lead?tab=table
A5: Increase of total DALY burden per year | C5: =(1+C4)^(1/41)-1 -> 0.0046601017 | D5: =(1+D4)^(1/41)-1 -> -0.001508018 | E5: =(1+E4)^(1/41)-1 -> 0.0032009233 | F5: %
A6: Total DALY burden Lead exposure GBD in 2024 | C6: =C3*(1+C5)^3 -> 940538.41 | D6: =D3*(1+D5)^3 -> 78238.972 | E6: =E3*(1+E5)^3 -> 132477.05 | F6: DALY
A7: Percentage attributable to informal ULAB recycling
B8: Directly due to informal ULAB recycling | C8: 0.35 | D8: 0.15 | E8: 0.15 | G8: Judgement, based on tab on 'overall GBD ULAB recycling' and upcoming paper from Forsyth I heard about which states that ULAB is 50% of lead poisoning in Dhaka, Bangladesh. Bret Ericson thinks it is somewhere around 10%, Hugo said that he stated 20% in the past. Note that it differs from place to place, but is hard to get over 50% with just paint, cookware and cosmetics. Potentially, ULAB recycling is cause more than 20%
B9: Due to Cookware | C9: 0.15 | D9: 0.15 | E9: 0.15 | G9: Intuition --> LeRA: help us out here!
B10: Counterfactual effect of fewer informal ULAB recycling on the burden due to Cookware | C10: 0.2 | D10: 0.2 | E10: 0.2 | G10: Intuition, Bret Ericson told me that in Mexico, both formal and informal recyclers sell lead (dust) to artisinal cookware makers.
B11: Additional contamination via grown crops near ULAB recycling plants/informal recyclers
A12: Percentage attributable to informal ULAB recycling | C12: =C8+C9*C10 -> 0.38 | D12: =D8+D9*D10 -> 0.18 | E12: =E8+E9*E10 -> 0.18
A13: Total DALY burden Lead exposure due to ULAB recycling in 2024 | C13: =C6*C12 -> 357404.59 | D13: =D6*D12 -> 14083.015 | E13: =E6*E12 -> 23845.868 | F13: DALY
A15: Decrease of total ULAB burden of a country when policies are improved substantially
A16: Model after Brazil
B17: Burden due to informal recycling in Brazil before improved regulation | C17: 0.8 | H17: Intutition
B18: Size of informal sector in Brazil before improved regulation | C18: 0.5 | H18: Carlos mentioned 45% , other sources claim 'the majority', so i went for 50%. Also, the blogpost mention some rough numbers, but that must have come from Carlos as well- https://leadbatteries.substack.com/p/how-brazil-solved-its-lead-acid-battery
B19: Size of informal sector in Brazil before after regulation | C19: 0.1 | H19: IBER has 75% of market in 2022, could expect this to have increased
B20: Decrease of size of informal recycling due to regulations | C20: =1-C19/C18 -> 0.8 | H20: Should check what happened in Brazil, I think it was about this size. Additionally: Mark stevenson made a judgementcall, that this would happen if taxes are cut in India on this.. Hugo: This number should be at least 50%. Best info he got on this was a quote: "most was informal before", Now 75% of the battery recycling is going via IBER. Also, Pure Earth states about 80% https://www.google.com/url?q=https://e360.yale.edu/features/getting-the-lead-out-why-battery-recycling-is-a-global-health-hazard%23:~:text%3DFuller%2520at%2520Pure%2520Earth%2520says,%252C%25E2%2580%259D%2520mainly%2520through%2520economic%2520incentives&sa=D&source=editors&ust=1733491202096199&usg=AOvVaw0aomdHgPlN28-Xc1QU9qWz
B21: Undiscounted decrease of total ULAB burden due to regulations | C21: =C17*C20 -> 0.64
A22: Discounts
B23: Improvement not being as large/effective in other countries (potentially as the problem at the start wasnt as big, i.e. the informal sector was smaller to start with) | C23: 0.15 | G23: Just intution, I consider this quite a big discount (thus being conservative)
B24: Decrease of informal leads to an increase in formal (which is better, but still not great) | C24: 0.05 | G24: Because informal is in populated area's and in so many more places
B25: When informal recyclers are gone: site is still contaminated indefenitely (untill cleaned) | C25: 0.4 | G25: Impact comes from Informal recyclers not relocating and no new informal recyclers starting. Carlos explained that as part of the Brazil legislation, one needs to clean up the plot before it can be used. Therefore, this is much a smaller problem. Updated the discount from 70% to 40%, as i expect this legislation not to be watertight, and potentially now viable to introduce in other countries.
B26: Growth of the ULAB market in the upcoming years | C26: =-average(1.04^7,1)+1 -> -0.15796589 | G26: Take 4% growth. This is quick and dirty, should put this in a proper model
A27: Decrease of total ULAB burden of a country when policies are improved substantially | C27: =C21*(1-C23)*(1-C24)*(1-C25)*(1-C26) -> 0.35906206
A29: Decrease of DALY burden when policies are implemented | C29: =C13*$C$27 -> 128330.43 | D29: =D13*$C$27 -> 5056.6764 | E29: =E13*$C$27 -> 8562.1466 | F29: DALY
A31: Probability of succes (improved policies are adopted) | C31: 0.05 | D31: 0.4 | E31: 0.35 | G31: Intuition
A32: Discount for enforcement not being as good as in Brazil | C32: 0.99 | D32: 0.1 | E32: 0.2 | G32: Intuition
A33: Expected decrease of DALY burden with advocacy initiative | C33: =C29*C31*(1-C32) -> 64.165216 | D33: =D29*D31*(1-D32) -> 1820.4035 | E33: =E29*E31*(1-E32) -> 2397.4011 | F33: DALY
A35: Years of counterfactual impact | C35: 7 | D35: =C35 -> 7 | E35: =D35 -> 7 | F35: Years | G35: Intuition, also given LEAF things might move a bit quicker
A36: Discount for time discounting | C36: 0.85 | D36: 0.85 | E36: 0.85 | F36: % | G36: Quick number to finish the calculation
A37: Total NPV Daly averted | C37: =C33*C35*C36 -> 381.78303 | D37: =D33*D35*D36 -> 10831.401 | E37: =E33*E35*E36 -> 14264.536 | F37: DALY
A39: Cost for the charity at scale | C39: ='Main CEA - Top down GBD'!B14 -> #REF! | D39: =C39 -> #REF! | E39: =D39 -> #REF! | F39: $
A40: Years needed for advocacy work | C40: 3 | D40: =C40 -> 3 | E40: =D40 -> 3 | F40: Amount | G40: Intuition, this might be optimistic?
A41: Total costs | C41: =C39*C40 -> #REF! | D41: =D39*D40 -> #REF! | E41: =E39*E40 -> #REF! | F41: $
A43: Cost-effectiveness (Dollar per daly) | C43: =C41/C37 -> #REF! | D43: =D41/D37 -> #REF! | E43: =E41/E37 -> #REF! | F43: $/Daly
A46: Remarks
B47: Consider looking at the CEA of Pure Earth by Givewell: https://docs.google.com/spreadsheets/d/1x0BchpoMphvAqSe71hJqM2gBByeRIf2oaz3WGVrVdow/edit?gid=109713399#gid=109713399

Sheet Top Down - BLL
A1: This CEA is moddeled after LeRA, which is a Blood lead level top down approach. Especially sensitive to the estimate of line 8
C2: Bangladesh | D2: Argentina | E2: Thailand | F2: Units | G2: Description | H2: Source
A3: BLL in Country | C3: 7.87 | D3: =AVERAGE(D4:D6) -> 2.96 | E3: 5.12 | F3: µg/dL | G3: This is 2019, just assume nothing changed, which is conservative probably. Note that Brazil was only 2.19 at the time | H3: https://ourworldindata.org/grapher/lead-concentrations-blood-children?tab=table
B4: Colombia | D4: 3.06
B5: Brazil | D5: 2.65
B6: Equador | D6: 3.17
A8: Reduction in BLL thanks to policies introduced | C8: 0.05 | F8: % change | G8: A guess. LeRA CEA had a higher number, (12.5%) but I consider that optimistic. Moddeled this loosely after the brazil model ( 20% due to ULAB, able to make that 25% better; which is a bit more optimistic than the brazil model sheet actually...)
A9: Intermediate effect size - reduction in BLL | C9: =C3*$C$8 -> 0.3935 | D9: =D3*$C$8 -> 0.148 | E9: =E3*$C$8 -> 0.256 | F9: μg/dL
A10: Internal validity effect [Suggest range 0% to -80%, e.g. -40%] | C10: 0 | F10: % change | G10: Not used (this is relevant when effect size is taken from a study)
A11: External validity effect [Suggest range +40% to -80%, e.g. -10%] | C11: 0 | F11: % change | G11: Not used
A12: Discounted effect size - reduction in BLL | C12: =C9*(1+$C$10)*(1+$C$11) -> 0.3935 | D12: =D9*(1+$C$10)*(1+$C$11) -> 0.148 | E12: =E9*(1+$C$10)*(1+$C$11) -> 0.256 | F12: μg/dL
A13: Estimated IQ point loss per 1 μg/dl increase in blood levels throughout childhood | C13: 0.15 | F13: IQ points per μg/dL | G13: Following GiveWell | H13: https://docs.google.com/document/d/1NH99fuXpXcCcz-vjaP1x3ZOVDNYd4gflWWb2B5y3TcQ/edit#heading=h.cqwbetxdrmad | I13: Thijs: LEEP uses a higher number, and also I don't see the used number straight away in the Give well linked doc
A14: IQ points gained per person | C14: =C12*$C$13 -> 0.059025 | D14: =D12*$C$13 -> 0.0222 | E14: =E12*$C$13 -> 0.0384 | F14: IQ points
A15: % increase in income (/consumption) for every 1 point increase in IQ | C15: 0.0067 | F15: % change | G15: From GiveWell | H15: https://docs.google.com/spreadsheets/d/15h60n8jDSQMFpmA_y4ilYOUE0mP-C9SRosEMHuWDnug/edit#gid=154585324
A16: % increase in income per person (in each year of working life) | C16: =C14*$C$15 -> 0.0003954675 | D16: =D14*$C$15 -> 0.00014874 | E16: =E14*$C$15 -> 0.00025728 | F16: % change
A17: Multiplier for resource sharing | C17: 2 | F17: coefficient | G17: Following GiveWell's reasoning: Each working adult's income benefits multiple people; on average ~2
A18: Conversion to consumption doublings | C18: =log(1+C16,2)*$C$17 -> 0.0011408524 | D18: =log(1+D16,2)*$C$17 -> 0.00042914101 | E18: =log(1+E16,2)*$C$17 -> 0.00074225768 | F18: ratio | G18: Assuming all extra income is consumed
A19: One year of doubled consumption to DALYs [fixed] | C19: =1/2.3 -> 0.43478261 | F19: ratio | G19: From GiveWell
A20: DALY equivlents per person per year of their working life | C20: =$C$19*C18 -> 0.0004960228 | D20: =$C$19*D18 -> 0.00018658305 | E20: =$C$19*E18 -> 0.00032272073 | F20: DEs/person/year
A21: Number of years of working life | C21: =65-20 -> 45 | F21: years | G21: Length of working life
A22: Discount rate for consumption impacts | C22: 0.04
A23: Total DALY-equivalent benefit over working life | C23: =-PV($C$22,$C$21,C20) -> 0.010277612 | D23: =-PV($C$22,$C$21,D20) -> 0.0038660081 | E23: =-PV($C$22,$C$21,E20) -> 0.0066867864 | F23: DEs/person
A24: Delay in benefits | C24: 15 | F24: years | G24: Age when people start working
A25: Present value of consumption benefit | C25: =C23*(1-$C$22)^$C$24 -> 0.0055713535 | D25: =D23*(1-$C$22)^$C$24 -> 0.0020957104 | E25: =E23*(1-$C$22)^$C$24 -> 0.0036248158 | F25: DEs/person
A26: Health benefit as a % of consumption benefit | C26: =16/84 -> 0.19047619 | F26: % | G26: For simplicity, I'm following LEEP, who estimate that health benefits make up 16% of the total. | H26: https://leadelimination.org/how-cost-effective-are-leeps-paint-programs/
A27: Present value of health benefit | C27: =$C$26*C25 -> 0.0010612102 | D27: =$C$26*D25 -> 0.00039918292 | E27: =$C$26*E25 -> 0.00069044111 | F27: DALYs/person
A28: Total net impact per person per year | C28: =C27+C25 -> 0.0066325637 | D28: =D27+D25 -> 0.0024948933 | E28: =E27+E25 -> 0.0043152569 | F28: DEs/person
A29: Births per country per year | C29: 3489953 | D29: 503823 | E29: 591200 | F29: Births, in 2023
A30: Total net impact per country per year | C30: =C28*C29 -> 23147.336 | D30: =D28*D29 -> 1256.9846 | E30: =E28*E29 -> 2551.1799 | F30: DEs/country
A32: Probability of succes (improved policies are adopted) | C32: 0.05 | D32: 0.4 | E32: 0.35 | G32: Intuition
A33: Expected net impact per country per year | C33: =C30*C32 -> 1157.3668 | D33: =D30*D32 -> 502.79385 | E33: =E30*E32 -> 892.91296 | F33: DEs/country
A35: Years of counterfactual impact | C35: 7 | D35: =C35 -> 7 | E35: =D35 -> 7 | F35: Years | G35: Intuition, also given LEAF things might move a bit quicker
A36: Discount for time discounting | C36: 0.85 | D36: 0.85 | E36: 0.85 | F36: % | G36: Quick number to finish the calculation
A37: Total NPV Daly averted | C37: =C33*C35*C36 -> 6886.3323 | D37: =D33*D35*D36 -> 2991.6234 | E37: =E33*E35*E36 -> 5312.8321 | F37: DEs
A39: Cost for the charity at scale | C39: ='Main CEA - Top down GBD'!B14 -> #REF! | D39: =C39 -> #REF! | E39: =D39 -> #REF! | F39: $
A40: Years needed for advocacy work | C40: 3 | D40: =C40 -> 3 | E40: =D40 -> 3 | F40: Amount | G40: Intuition, this might be optimistic?
A41: Total costs | C41: =C39*C40 -> #REF! | D41: =D39*D40 -> #REF! | E41: =E39*E40 -> #REF! | F41: $
A43: Cost-effectiveness (Dollar per daly) | C43: =C41/C37 -> #REF! | D43: =D41/D37 -> #REF! | E43: =E41/E37 -> #REF! | F43: $/Daly-equivalent

Sheet Overall GBD ULAB recycling
D2: Lower estimate (10%) | E2: Best-guess (50%) | F2: High estimate(90%) | G2: Units | H2: Description | I2: Source
A3: Informal recycling | B3: Estimate DALY burden in 2013 by researchers of *Informal recycling* (90 countries) | D3: 0.127248 | E3: =AVERAGE(D3,F3) -> 0.869862 | F3: 1.612476 | G3: Million DALY | H3: Based on paper, best guess is average | I3: https://annalsofglobalhealth.org/articles/231/files/submission/proof/231-1-536-1-10-20180511.pdf
B4: Correct for being conservative
C5: Correction for predictions of increase in BLL are lower than actual BLL found in studies | D5: 0.05 | E5: 0.15 | F5: 0.25 | G5: % | H5: "We further stated that these predictions are much lower than actual the BLLs found by researchers at sites in the field53-57 and that our predictions are very likely underestimates."
C6: Correction detailed vs. limited assesment page 6 | D6: 0.1 | E6: 0.25 | F6: 0.5 | G6: % | H6: Unclear how much a increase in soil translate to the overall increase in a burden
B7: Improved estimate DALY burden 2013 | D7: =D3*(1+D5)*(1+D6) -> 0.14697144 | E7: =E3*(1+E5)*(1+E6) -> 1.2504266 | F7: =F3*(1+F5)*(1+F6) -> 3.0233925 | G7: Million DALY
B8: Growth of market per year | D8: 0.03 | E8: 0.04 | F8: 0.05 | G8: % | H8: Quick numbers, based on what I think I have read in places. Should be easy to source from the internet
B9: Number of years since 2013 | D9: =2024-2013 -> 11 | E9: =D9 -> 11 | F9: =E9 -> 11 | G9: Years
B10: Undiscounted estimate of Daly Burden 2024 | D10: =D7*(1+D8)^D9 -> 0.20344285 | E10: =E7*(1+E8)^E9 -> 1.9249743 | F10: =F7*(1+F8)^F9 -> 5.1710272 | G10: Million DALY
B11: Discount for less recycling being done by informal recyclers | D11: 0.4 | E11: 0.2 | F11: 0.1 | G11: % | H11: Andreas mentioned it is limited in Africa but still seems rampant in Asia. So expect share to be similar in Asia, and less so in Africa. I expect the market in Asia to be bigger
B12: Updated estimate of DALY burden 2024 | D12: =D10*(1-D11) -> 0.12206571 | E12: =E10*(1-E11) -> 1.5399795 | F12: =F10*(1-F11) -> 4.6539245 | G12: Million DALY
B14: Total DALY burden lead exposure GBD in 2021 | D14: 33.89055 | E14: 33.89055 | F14: 33.89055 | G14: Million DALY | I14: https://ourworldindata.org/grapher/disease-burden-lead?tab=table
B15: Increase of total DALY burden per year | D15: =(1+0.55)^(1/41)-1 -> 0.010746478 | E15: =D15 -> 0.010746478 | F15: =E15 -> 0.010746478 | G15: % | H15: Based on trajectory since 1990 | I15: https://ourworldindata.org/grapher/disease-burden-lead?tab=table
B16: Total DALY burden lead exposure GBD in 2024 | D16: =D14*(1+D15)^3 -> 34.994946 | E16: =E14*(1+E15)^3 -> 34.994946 | F16: =F14*(1+F15)^3 -> 34.994946 | G16: Million DALY
B17: Discount for the fact that the paper only looks at 90 contries, rather than all 238 countries | D17: 0.2 | E17: 0.2 | F17: 0.2 | H17: This is a guess. The paper looked at 90 LMIC countries. So DALY burden outside of that should be limited, but does leave out HICS, which might altogether have some part of the burden. They did leave out the balkans and countries in conflict (e.g. Syria)
B18: Total DALY burden Lead exposure GBD in 2024 for the 90 countries | D18: =D16*(1-D17) -> 27.995957 | E18: =E16*(1-E17) -> 27.995957 | F18: =F16*(1-F17) -> 27.995957
B19: Percentage attributable to informal ULAB recycling | D19: =D12/D18 -> 0.0043601192 | E19: =E12/E18 -> 0.05500721 | F19: =F12/F18 -> 0.16623559
A21: Formal recycling | B21: Amount of informal recycler for every formal recycler
C22: Total number of informal recyclers in all 90 countries in 2013 | D22: 30000 | E22: =AVERAGE(D22,F22) -> 20000 | F22: 10000 | G22: Amount | H22: Based on paper, best guess is average | I22: https://annalsofglobalhealth.org/articles/231/files/submission/proof/231-1-536-1-10-20180511.pdf
C23: Total number of informal recyclers in all 90 countries in 2024 | D23: =D22*(1+D8)^D9 -> 41527.016 | E23: =E22*(1+E8)^E9 -> 30789.081 | F23: =F22*(1+F8)^F9 -> 17103.394 | G23: Amount
C24: Estimate of average amount of formal recyclers per country | D24: 2 | E24: 5 | F24: 10 | G24: Amount | H24: Intuition, might be much higher if you also incorporate the informal but large recyclers (unclear if paper includes these)
C25: Total amount of formal recyclers | D25: =D24*90 -> 180 | E25: =E24*90 -> 450 | F25: =F24*90 -> 900 | G25: Amount
C26: Amount of informal recycler for every formal recycler | D26: =D23/D25 -> 230.70565 | E26: =E23/E25 -> 68.42018 | F26: =F23/F25 -> 19.003771 | G26: Amount
B27: Undiscounted additional DALY due to formal recycling | D27: =D12/D26 -> 0.00052909718 | E27: =E12/E26 -> 0.022507679 | F27: =F12/F26 -> 0.24489479 | G27: Million DALY
B28: More contamination per formal site, because troughput is higher | D28: 1.5 | E28: 3 | F28: 5 | G28: Factor | H28: Intution
B29: Discount for formal sites being less so in populated areas | D29: 0.8 | E29: 0.6 | F29: 0.3 | G29: %
B30: Discounted additional DALY due to formal recycling | D30: =D27*D28*(1-D29) -> 0.00015872916 | E30: =E27*E28*(1-E29) -> 0.027009215 | F30: =F27*F28*(1-F29) -> 0.85713177 | G30: Million DALY
B31: Sanity check - formal recyclers account for x% of total burden of ULAB recycling | D31: =D30/D33 -> 0.0012986696 | E31: =E30/E33 -> 0.017236382 | F31: =F30/F33 -> 0.15552949 | G31: %
A33: Total burden of ULAB recycling in 2024 in the 90 countries | D33: =D30+D12 -> 0.12222444 | E33: =E30+E12 -> 1.5669887 | F33: =F30+F12 -> 5.5110562 | G33: Million DALY
A34: Total burden of lead exposure in 2024 in the 90 countries | D34: =D18 -> 27.995957 | E34: =E18 -> 27.995957 | F34: =F18 -> 27.995957 | G34: Million DALY | H34: IHME
A35: Percentage of Lead exposure burden attributable to ULAB recycling | D35: =D33/D34 -> 0.0043657889 | E35: =E33/E34 -> 0.055971964 | F35: =F33/F34 -> 0.19685186 | G35: %

Sheet Bottom Up
C1: Bangladesh | D1: Argentina | E1: Thailand | F1: Units | G1: Description | H1: Source
A2: Total DALY burden in 90 countries | C2: ='Overall GBD ULAB recycling'!E3*10^6 -> 869862 | F2: DALY | H2: Paper by Bret Ericson: https://annalsofglobalhealth.org/articles/231/files/submission/proof/231-1-536-1-10-20180511.pdf
A3: Amount of Informal recyclers | C3: =Average(10599,29241) -> 19920 | F3: Amount of sites | H3: Paper by Bret Ericson: https://annalsofglobalhealth.org/articles/231/files/submission/proof/231-1-536-1-10-20180511.pdf
A4: Naive average DALY burden per informal site | C4: =C2/C3 -> 43.667771 | F4: DALY / site
A5: Discount for being densely populated compared to average | C5: -0.3 | D5: 0.1 | E5: 0 | F5: % | H5: Intution
A6: Daly burden per informal site | C6: =$C$4*(1-C5) -> 56.768102 | D6: =$C$4*(1-D5) -> 39.300994 | E6: =$C$4*(1-E5) -> 43.667771 | F6: DALY / site
A8: Overall population | C8: 171466986 | D8: 45538402 | E8: 71702438 | H8: https://ourworldindata.org/grapher/population?tab=table
A9: Size of ULAB market compared to Bangladesh [Very naive] | C9: =C8/$C$8 -> 1 | D9: =D8/$C$8 -> 0.26558117 | E9: =E8/$C$8 -> 0.41817052 | G9: This is naive, I think ULAB is comperatively big in Bangladesh, so wouldn't scale with population directly
A10: Amount of informal sites per country | C10: 1300 | D10: =C10*D9 -> 345.25552 | E10: =C10*E9 -> 543.62167 | F10: Informal recycling sites per country | H10: https://www.unep.org/topics/chemicals-and-pollution-action/pollution-and-health/heavy-metals/used-lead-acid-batteries claims there are over 1.100 sites in Bangladesh.
A11: Total DALY burden per country due to informal ULAB recycling | C11: =C10*C6 -> 73798.533 | D11: =D10*D6 -> 13568.885 | E11: =E10*E6 -> 23738.747
A14: From here onwards: Similar to the Top down approach!
A15: Decrease of total ULAB burden of a country when policies are improved substantially | C15: =' Top Down - GBD'!C27 -> 0.35906206
A17: Decrease of DALY burden when policies are implemented | C17: =$C$15*C11 -> 26498.254 | D17: =$C$15*D11 -> 4872.0718 | E17: =$C$15*E11 -> 8523.6834 | F17: DALY
A19: Probability of succes (improved policies are adopted) | C19: 0.05 | D19: 0.2 | E19: 0.1 | G19: Intuition
A20: Discount for enforcement not being as good as in Brazil | C20: 0.4 | D20: 0.2 | E20: 0.3 | G20: Intuition
A21: Expected decrease of DALY burden with advocacy initiative | C21: =C17*C19*(1-C20) -> 794.94761 | D21: =D17*D19*(1-D20) -> 779.53149 | E21: =E17*E19*(1-E20) -> 596.65783 | F21: DALY
A23: Years of counterfactual impact | C23: 7 | D23: =C23 -> 7 | E23: =D23 -> 7 | F23: Years | G23: Intuition, also given LEAF things might move a bit quicker
A24: Discount for time discounting | C24: 0.85 | D24: 0.85 | E24: 0.85 | F24: % | G24: Quick number to finish the calculation
A25: Total NPV Daly averted | C25: =C21*C23*C24 -> 4729.9383 | D25: =D21*D23*D24 -> 4638.2124 | E25: =E21*E23*E24 -> 3550.1141 | F25: DALY
A27: Cost for the charity at scale | C27: ='Main CEA - Top down GBD'!B14 -> #REF! | D27: =C27 -> #REF! | E27: =D27 -> #REF! | F27: $
A28: Years needed for advocacy work | C28: 3 | D28: =C28 -> 3 | E28: =D28 -> 3 | F28: Amount | G28: Intuition, this might be optimistic?
A29: Total costs | C29: =C27*C28 -> #REF! | D29: =D27*D28 -> #REF! | E29: =E27*E28 -> #REF! | F29: $
A31: Cost-effectiveness (Dollar per daly) | C31: =C29/C25 -> #REF! | D31: =D29/D25 -> #REF! | E31: =E29/E25 -> #REF! | F31: $/Daly

Sheet OLD 2023 CEA
A1: =IFERROR(IF(K4*L4*SUM(I3:I251)+COUNTA(I3:I251)=0,"Inputs",1/0),"YOU HAVE EDITED ROWS J K or L – PLEASE DO NOT DO THIS") -> Inputs | B1: Expected | C1: UseCarlo | D1: p05 | E1: p95 | F1: Param1 | G1: Param2 | H1: Param3 | I1: NO EDIT | J1: Units | K1: Distr. mean | L1: Distr. median | N1: Description | O1: Source | P1: Comments | Q1: Replies
A2: Description of intervention | I2: DO NOT EDIT COLUMN | K2: FORMULA DO NOT EDIT THIS COLUMN
A3: [Fill out description here]
A4: Geographic focus of this CEA | B4: [country / region] | K4: {=SWITCH(C4:C223, "Normal", (D4:D223+E4:E223)/2, "Lognormal", EXP((LN(D4:D223)+LN(E4:E223))/2 + ((LN(E4:E223)-(LN(D4:D223)+LN(E4:E223))/2)/1.645)^2/2), "Beta", F4:F223/(F4:F223+G4:G223), "", "", "output", "")} | L4: {=SWITCH(C4:C223, "Normal", (D4:D223+E4:E223)/2, "Lognormal", EXP((LN(D4:D223)+LN(E4:E223))/2), "Beta", "Not Implemented", "", "", "output", "")}
A7: Tractability & counterfactuals
A8: Probability of success etc
A9: Probability per year that change would happen anyway (even if no charity) | J9: %
A10: In case useful: Number yrs until 50%+ change happens anyway | B10: =IFERROR(LOG(0.5,(1-B9)),"never") -> never
A11: Probability of success (that the expected impact happens) [suggest: 90% for direct, 30% for policy] | B11: 0.9 | C11: Beta | D11: 0.85 | E11: 0.95 | J11: % | K11: #DIV/0! | L11: Not Implemented
A12: Last year charity runs if unsuccessful [suggest: 4] | B12: 4 | C12: Normal | D12: 1 | E12: 6 | J12: years | K12: 3.5 | L12: 3.5
A13: =" In case useful: Total prob. change happens in timeframe ("&B12&"yrs)" -> In case useful: Total prob. change happens in timeframe (4yrs) | B13: =1-(1-B11)*(1-B9)^B12 -> 0.9
A16: Costs
A17: Key assumptions
A18: Discount rate, for costs [keep fixed in all CEAs] | B18: 0.04 | J18: %
A20: 1. FIXED CHARITY COSTS
A21: Period 1 – initial scaling | N21: This section assumes a linear increase in fixed costs during the scaling period
A22: Cost period 1 begins in year __ [fixed] | B22: 1 | J22: Year
A23: Cost period 1 ends in year __ [suggest: 2-5; min: 2] | B23: 3 | C23: Normal | D23: 2 | E23: 4 | J23: Year | K23: 3 | L23: 3 | N23: Period inclusive of this year
A24: Costs at period 1 start [fixed, based on CE grant sizes] | B24: 130000 | C24: LogNormal | D24: 100000 | E24: 170000 | J24: $ | K24: 132090.96 | L24: 130384.05 | N24: Estimate (from Joey) for 90% confidence interval for CE seed grant is $100k to $190k | O24: -
A25: Costs at period 1 end [default: $250,000] | B25: 250000 | C25: LogNormal | D25: 150000 | E25: 400000 | J25: $ | K25: 256079.77 | L25: 244948.97
A26: Total fixed costs over period 1, NPV | B26: =B30*(1-B$18)^(B22-1) -> 542800 | J26: $
A27: Increase per year | B27: =(B25-B24)/(B23-B22) -> 60000 | J27: $
A28: Total length of period | B28: =B23-B22+1 -> 3 | J28: years
A29: Cumulative discount multiplier over period | B29: =(1-B$18)^B28 -> 0.884736 | J29: %
A30: Total fixed costs of period at starting year of period | B30: =((B24*((1-B29)) + B27*((1-B29)/(B$18)-1-(B28-1)*B29)) /(B$18)) -> 542800 | J30: $ | N30: Formula based on SUM (a+kb)r^k, where k is variable 0→year (C10) and a is base cost (C19) and b is annual addition (C14) and r is the discount rate (C5)
A31: Total fixed costs over period, NPV (single line formula version) | B31: =((B24*((1-(1-B$18)^(B23-B22+1))) + ((B25-B24)/(B23-B22))*((1-(1-B$18)^(B23-B22+1))/(B$18)-1-((B23-B22+1)-1)*(1-B$18)^(B23-B22+1))) /(B$18)) *(1-B$64)^(B22-1) -> 542800 | J31: $
A32: Total fixed costs over period 1, NPV, if not successful | B32: =IF(B$12<B22,0, IF(B$12>B23,B26, ((B24*((1-(1-B$18)^(B$12-B22+1))) + B27*((1-(1-B$18)^(B$12-B22+1))/(B$18)-1-((B$12-B22+1)-1)*(1-B$18)^(B$12-B22+1))) /(B$18)) *(1-B$18)^(B22-1) )) -> 542800 | J32: $
A33: Period 2 – ongoing costs | B33: ← Can copy and paste these rows (or section above) to add additional costing periods below
A34: Cost period 2 begins in year ___ [previous period end +1] | B34: =B23+1 -> 4 | J34: Year
A35: Cost period 2 ends on year ___ OR "ongoing" [suggest: 16] | B35: 16 | C35: LogNormal | D35: 5 | E35: 35 | J35: Year | K35: 15.757346 | L35: 13.228757
A36: Annual fixed costs in this period | B36: =B25 -> 250000 | J36: $ | O36: -
A37: Total fixed costs over period 2, NPV | B37: =(IF(B35="ongoing", B36/B$18, B36*((1-(1-B$18)^B35))/(B$18)) - B36*((1-(1-B$18)^(B34-1)))/(B$18)) *(1-B$18)^(B34-1) -> 2014616.2 | J37: $
A38: Total fixed costs over period 2, NPV, if not successful | B38: =IF(B$12<B34,0,IF(B$12>B35,B37, B36*((1-(1-B$18)^B$12))/(B$18) - B36*((1-(1-B$18)^(B34-1)))/(B$18) )) *(1-B$18)^(B34-1) -> 195689.45 | J38: $
A41: 2. VARIABLE CHARITY COSTS
A42: [Subheading]
A43: Cost of intervention per person | J43: $/person
A44: Variable costs per [group] (for staff/training/set-up/etc) | J44: $
A45: Number of people reached [by/in] in each [group/etc] | J45: person
A46: Total cost per person | B46: =B43+IF(B45="",0,B44/B45) -> 0 | J46: $/person
A47: Number of people reached, NPV | B47: =B126 -> #DIV/0! | J47: people
...

Sheet Median salaries
A1: 0. DUPLICATE TEMPLATE BEFORE USE | B1: CALCAULTIONS | F1: ↓ NOTE: If you want more columns, you have to: add a column to the right of column F and copy column F equations to the new column. Do the same for column I. Repeat to as many columns as you want | G1: ↓ 3. ADD DATA HEADINGS | I1: ↓ NOTE: If you want more columns, you have to: add a column to the right of column F and copy column F equations to the new column. Do the same for column I. Repeat to as many columns as you want | K1: 2. FILL OUT THESE | L1: =IF(COUNTIF(L3:L1001,"ERROR – NOT LISTED. Add alt spelling to ''Countries'' tab")>1,"CHECK SPELLINGS","") | M1: 1. COPY DATA HERE ↓ make sure data headings are in the top row and country names in the first column | W1: ↓ Can do calcaultions on data here if you need to ↓
A2: CE Country list | B2: Region | C2: Country MATCH position | D2: =G2 -> Median salary of working people | E2: =H2 | F2: =I2 | G2: Median salary of working people | L2: Headings: | M2: Country | N2: Median income or consumption (2017 $) | O2: Annual income (2024 $) | P2: % working age | Q2: Unemployment | R2: Median salary of working people
A3: =Countries!B2 -> Afghanistan | B3: =Countries!I2 -> South Asia | C3: =IFERROR(IFERROR(IFERROR(IFERROR(IFERROR(IFERROR(IFERROR(MATCH(Countries!$B2,$M$3:$M$1003,0),MATCH(Countries!$C2,$M$3:$M$1003,0)),MATCH(Countries!$D2,$M$3:$M$1003,0)),MATCH(Countries!$E2,$M$3:$M$1003,0)),MATCH(Countries!$F2,$M$3:$M$1003,0)),MATCH(Countries!$G2,$M$3:$M$1003,0)),MATCH(Countries!$H2,$M$3:$M$1003,0)),"X") -> 1 | D3: =IF(G$2="","",IF($C3="X","",INDEX($N$3:$CC$1003,$C3,MATCH(G$2,$N$2:$CC$2,0)))) -> 7827.0018 | E3: =IF(H$2="","",IF($C3="X","",INDEX($N$3:$CC$1003,$C3,MATCH(H$2,$N$2:$CC$2,0)))) | F3: =IF(I$2="","",IF($C3="X","",INDEX($N$3:$CC$1003,$C3,MATCH(I$2,$N$2:$CC$2,0)))) | G3: =IF(A3="","",IF(G$2="","", IF(D3="",IF($K$16="Use global average",D$276,IF($K$16="Use regional average",INDEX(D$280:D$296,MATCH($B3,$B$280:$B$296,0)),IF($K$16="Leave blank","",IF($K$16="Fill with zeros", 0,IF($K$16="Use global median",D$277,"Fill out I16"))))), D3))) -> 7827.0018 | H3: =IF(H$2="","", IF(E3="",IF($K$16="Use global average",E$276,IF($K$16="Use regional average",INDEX(E$280:E$296,MATCH($B3,$B$280:$B$296,0)),IF($K$16="Leave blank","",IF($K$16="Fill with zeros", 0,IF($K$16="Use global median",E$277,"Fill out I16"))))), E3)) | I3: =IF(I$2="","", IF(F3="",IF($K$16="Use global average",F$276,IF($K$16="Use regional average",INDEX(F$280:F$296,MATCH($B3,$B$280:$B$296,0)),IF($K$16="Leave blank","",IF($K$16="Fill with zeros", 0,IF($K$16="Use global median",F$277,"Fill out I16"))))), F3)) | J3: ← 4. COPY – Use a forumula to inport data OR copy and paste data into: "Data summary" tab | L3: =IF(M3="","",IF(COUNTIF(Countries!$B$1:$H$271,M3)>0,"",IF(COUNTIF(Countries!$M$1:$S$271,M3)>0,"Not a country","ERROR – NOT LISTED. Add alt spelling to ''Countries'' tab"))) | M3: Afghanistan | N3: NA | O3: =N4*365*1.28 -> 5636.6311 | P3: 0.8383609 | Q3: 0.141 | R3: =IFERROR(O3/(P3*(1-Q3)),"") -> 7827.0018
A4: =Countries!B3 -> Albania | B4: =Countries!I3 -> Europe | C4: =IFERROR(IFERROR(IFERROR(IFERROR(IFERROR(IFERROR(IFERROR(MATCH(Countries!$B3,$M$3:$M$1003,0),MATCH(Countries!$C3,$M$3:$M$1003,0)),MATCH(Countries!$D3,$M$3:$M$1003,0)),MATCH(Countries!$E3,$M$3:$M$1003,0)),MATCH(Countries!$F3,$M$3:$M$1003,0)),MATCH(Countries!$G3,$M$3:$M$1003,0)),MATCH(Countries!$H3,$M$3:$M$1003,0)),"X") -> 2 | D4: =IF(G$2="","",IF($C4="X","",INDEX($N$3:$CC$1003,$C4,MATCH(G$2,$N$2:$CC$2,0)))) -> 0 | E4: =IF(H$2="","",IF($C4="X","",INDEX($N$3:$CC$1003,$C4,MATCH(H$2,$N$2:$CC$2,0)))) | F4: =IF(I$2="","",IF($C4="X","",INDEX($N$3:$CC$1003,$C4,MATCH(I$2,$N$2:$CC$2,0)))) | G4: =IF(A4="","",IF(G$2="","", IF(D4="",IF($K$16="Use global average",D$276,IF($K$16="Use regional average",INDEX(D$280:D$296,MATCH($B4,$B$280:$B$296,0)),IF($K$16="Leave blank","",IF($K$16="Fill with zeros", 0,IF($K$16="Use global median",D$277,"Fill out I16"))))), D4))) -> 0 | H4: =IF(H$2="","", IF(E4="",IF($K$16="Use global average",E$276,IF($K$16="Use regional average",INDEX(E$280:E$296,MATCH($B4,$B$280:$B$296,0)),IF($K$16="Leave blank","",IF($K$16="Fill with zeros", 0,IF($K$16="Use global median",E$277,"Fill out I16"))))), E4)) | I4: =IF(I$2="","", IF(F4="",IF($K$16="Use global average",F$276,IF($K$16="Use regional average",INDEX(F$280:F$296,MATCH($B4,$B$280:$B$296,0)),IF($K$16="Leave blank","",IF($K$16="Fill with zeros", 0,IF($K$16="Use global median",F$277,"Fill out I16"))))), F4)) | K4: DATA DESCRIPTION | L4: =IF(M4="","",IF(COUNTIF(Countries!$B$1:$H$271,M4)>0,"",IF(COUNTIF(Countries!$M$1:$S$271,M4)>0,"Not a country","ERROR – NOT LISTED. Add alt spelling to ''Countries'' tab"))) | M4: Albania | N4: 12.064707 | P4: 0.50014008 | Q4: 0.11629 | R4: =IFERROR(O4/(P4*(1-Q4)),"") -> 0
A5: =Countries!B4 -> Algeria | B5: =Countries!I4 -> North Africa | C5: =IFERROR(IFERROR(IFERROR(IFERROR(IFERROR(IFERROR(IFERROR(MATCH(Countries!$B4,$M$3:$M$1003,0),MATCH(Countries!$C4,$M$3:$M$1003,0)),MATCH(Countries!$D4,$M$3:$M$1003,0)),MATCH(Countries!$E4,$M$3:$M$1003,0)),MATCH(Countries!$F4,$M$3:$M$1003,0)),MATCH(Countries!$G4,$M$3:$M$1003,0)),MATCH(Countries!$H4,$M$3:$M$1003,0)),"X") -> 3 | D5: =IF(G$2="","",IF($C5="X","",INDEX($N$3:$CC$1003,$C5,MATCH(G$2,$N$2:$CC$2,0)))) -> 7307.1808 | E5: =IF(H$2="","",IF($C5="X","",INDEX($N$3:$CC$1003,$C5,MATCH(H$2,$N$2:$CC$2,0)))) | F5: =IF(I$2="","",IF($C5="X","",INDEX($N$3:$CC$1003,$C5,MATCH(I$2,$N$2:$CC$2,0)))) | G5: =IF(A5="","",IF(G$2="","", IF(D5="",IF($K$16="Use global average",D$276,IF($K$16="Use regional average",INDEX(D$280:D$296,MATCH($B5,$B$280:$B$296,0)),IF($K$16="Leave blank","",IF($K$16="Fill with zeros", 0,IF($K$16="Use global median",D$277,"Fill out I16"))))), D5))) -> 7307.1808 | H5: =IF(H$2="","", IF(E5="",IF($K$16="Use global average",E$276,IF($K$16="Use regional average",INDEX(E$280:E$296,MATCH($B5,$B$280:$B$296,0)),IF($K$16="Leave blank","",IF($K$16="Fill with zeros", 0,IF($K$16="Use global median",E$277,"Fill out I16"))))), E5)) | I5: =IF(I$2="","", IF(F5="",IF($K$16="Use global average",F$276,IF($K$16="Use regional average",INDEX(F$280:F$296,MATCH($B5,$B$280:$B$296,0)),IF($K$16="Leave blank","",IF($K$16="Fill with zeros", 0,IF($K$16="Use global median",F$277,"Fill out I16"))))), F5)) | L5: =IF(M5="","",IF(COUNTIF(Countries!$B$1:$H$271,M5)>0,"",IF(COUNTIF(Countries!$M$1:$S$271,M5)>0,"Not a country","ERROR – NOT LISTED. Add alt spelling to ''Countries'' tab"))) | M5: Algeria | N5: 8.04364 | O5: =N5*365*1.28 -> 3757.9886 | P5: 0.5876962 | Q5: 0.12491 | R5: =IFERROR(O5/(P5*(1-Q5)),"") -> 7307.1808
A6: =Countries!B5 -> Andorra | B6: =Countries!I5 -> Europe | C6: =IFERROR(IFERROR(IFERROR(IFERROR(IFERROR(IFERROR(IFERROR(MATCH(Countries!$B5,$M$3:$M$1003,0),MATCH(Countries!$C5,$M$3:$M$1003,0)),MATCH(Countries!$D5,$M$3:$M$1003,0)),MATCH(Countries!$E5,$M$3:$M$1003,0)),MATCH(Countries!$F5,$M$3:$M$1003,0)),MATCH(Countries!$G5,$M$3:$M$1003,0)),MATCH(Countries!$H5,$M$3:$M$1003,0)),"X") -> 4 | D6: =IF(G$2="","",IF($C6="X","",INDEX($N$3:$CC$1003,$C6,MATCH(G$2,$N$2:$CC$2,0)))) | E6: =IF(H$2="","",IF($C6="X","",INDEX($N$3:$CC$1003,$C6,MATCH(H$2,$N$2:$CC$2,0)))) | F6: =IF(I$2="","",IF($C6="X","",INDEX($N$3:$CC$1003,$C6,MATCH(I$2,$N$2:$CC$2,0)))) | G6: =IF(A6="","",IF(G$2="","", IF(D6="",IF($K$16="Use global average",D$276,IF($K$16="Use regional average",INDEX(D$280:D$296,MATCH($B6,$B$280:$B$296,0)),IF($K$16="Leave blank","",IF($K$16="Fill with zeros", 0,IF($K$16="Use global median",D$277,"Fill out I16"))))), D6))) -> 33026.356 | H6: =IF(H$2="","", IF(E6="",IF($K$16="Use global average",E$276,IF($K$16="Use regional average",INDEX(E$280:E$296,MATCH($B6,$B$280:$B$296,0)),IF($K$16="Leave blank","",IF($K$16="Fill with zeros", 0,IF($K$16="Use global median",E$277,"Fill out I16"))))), E6)) | I6: =IF(I$2="","", IF(F6="",IF($K$16="Use global average",F$276,IF($K$16="Use regional average",INDEX(F$280:F$296,MATCH($B6,$B$280:$B$296,0)),IF($K$16="Leave blank","",IF($K$16="Fill with zeros", 0,IF($K$16="Use global median",F$277,"Fill out I16"))))), F6)) | K6: Calculating median salary based on data on median per-capita income. | L6: =IF(M6="","",IF(COUNTIF(Countries!$B$1:$H$271,M6)>0,"",IF(COUNTIF(Countries!$M$1:$S$271,M6)>0,"Not a country","ERROR – NOT LISTED. Add alt spelling to ''Countries'' tab"))) | M6: Andorra | N6: NA | O6: =N6*365*1.28 -> #VALUE! | P6: 0.3824098 | Q6: #VALUE! | R6: =IFERROR(O6/(P6*(1-Q6)),"") | S6: =IFERROR(R6,"")
A7: =Countries!B6 -> Angola | B7: =Countries!I6 -> Sub-Saharan Africa | C7: =IFERROR(IFERROR(IFERROR(IFERROR(IFERROR(IFERROR(IFERROR(MATCH(Countries!$B6,$M$3:$M$1003,0),MATCH(Countries!$C6,$M$3:$M$1003,0)),MATCH(Countries!$D6,$M$3:$M$1003,0)),MATCH(Countries!$E6,$M$3:$M$1003,0)),MATCH(Countries!$F6,$M$3:$M$1003,0)),MATCH(Countries!$G6,$M$3:$M$1003,0)),MATCH(Countries!$H6,$M$3:$M$1003,0)),"X") -> 5 | D7: =IF(G$2="","",IF($C7="X","",INDEX($N$3:$CC$1003,$C7,MATCH(G$2,$N$2:$CC$2,0)))) -> 2074.9561 | E7: =IF(H$2="","",IF($C7="X","",INDEX($N$3:$CC$1003,$C7,MATCH(H$2,$N$2:$CC$2,0)))) | F7: =IF(I$2="","",IF($C7="X","",INDEX($N$3:$CC$1003,$C7,MATCH(I$2,$N$2:$CC$2,0)))) | G7: =IF(A7="","",IF(G$2="","", IF(D7="",IF($K$16="Use global average",D$276,IF($K$16="Use regional average",INDEX(D$280:D$296,MATCH($B7,$B$280:$B$296,0)),IF($K$16="Leave blank","",IF($K$16="Fill with zeros", 0,IF($K$16="Use global median",D$277,"Fill out I16"))))), D7))) -> 2074.9561 | H7: =IF(H$2="","", IF(E7="",IF($K$16="Use global average",E$276,IF($K$16="Use regional average",INDEX(E$280:E$296,MATCH($B7,$B$280:$B$296,0)),IF($K$16="Leave blank","",IF($K$16="Fill with zeros", 0,IF($K$16="Use global median",E$277,"Fill out I16"))))), E7)) | I7: =IF(I$2="","", IF(F7="",IF($K$16="Use global average",F$276,IF($K$16="Use regional average",INDEX(F$280:F$296,MATCH($B7,$B$280:$B$296,0)),IF($K$16="Leave blank","",IF($K$16="Fill with zeros", 0,IF($K$16="Use global median",F$277,"Fill out I16"))))), F7)) | L7: =IF(M7="","",IF(COUNTIF(Countries!$B$1:$H$271,M7)>0,"",IF(COUNTIF(Countries!$M$1:$S$271,M7)>0,"Not a country","ERROR – NOT LISTED. Add alt spelling to ''Countries'' tab"))) | M7: Angola | N7: 3.4205022 | O7: =N7*365*1.28 -> 1598.0586 | P7: 0.9005461 | Q7: 0.14478 | R7: =IFERROR(O7/(P7*(1-Q7)),"") -> 2074.9561
A8: =Countries!B7 -> Antigua and Barbuda | B8: =Countries!I7 -> Caribbean | C8: =IFERROR(IFERROR(IFERROR(IFERROR(IFERROR(IFERROR(IFERROR(MATCH(Countries!$B7,$M$3:$M$1003,0),MATCH(Countries!$C7,$M$3:$M$1003,0)),MATCH(Countries!$D7,$M$3:$M$1003,0)),MATCH(Countries!$E7,$M$3:$M$1003,0)),MATCH(Countries!$F7,$M$3:$M$1003,0)),MATCH(Countries!$G7,$M$3:$M$1003,0)),MATCH(Countries!$H7,$M$3:$M$1003,0)),"X") -> 6 | D8: =IF(G$2="","",IF($C8="X","",INDEX($N$3:$CC$1003,$C8,MATCH(G$2,$N$2:$CC$2,0)))) | E8: =IF(H$2="","",IF($C8="X","",INDEX($N$3:$CC$1003,$C8,MATCH(H$2,$N$2:$CC$2,0)))) | F8: =IF(I$2="","",IF($C8="X","",INDEX($N$3:$CC$1003,$C8,MATCH(I$2,$N$2:$CC$2,0)))) | G8: =IF(A8="","",IF(G$2="","", IF(D8="",IF($K$16="Use global average",D$276,IF($K$16="Use regional average",INDEX(D$280:D$296,MATCH($B8,$B$280:$B$296,0)),IF($K$16="Leave blank","",IF($K$16="Fill with zeros", 0,IF($K$16="Use global median",D$277,"Fill out I16"))))), D8))) -> 12713.18 | H8: =IF(H$2="","", IF(E8="",IF($K$16="Use global average",E$276,IF($K$16="Use regional average",INDEX(E$280:E$296,MATCH($B8,$B$280:$B$296,0)),IF($K$16="Leave blank","",IF($K$16="Fill with zeros", 0,IF($K$16="Use global median",E$277,"Fill out I16"))))), E8)) | I8: =IF(I$2="","", IF(F8="",IF($K$16="Use global average",F$276,IF($K$16="Use regional average",INDEX(F$280:F$296,MATCH($B8,$B$280:$B$296,0)),IF($K$16="Leave blank","",IF($K$16="Fill with zeros", 0,IF($K$16="Use global median",F$277,"Fill out I16"))))), F8)) | L8: =IF(M8="","",IF(COUNTIF(Countries!$B$1:$H$271,M8)>0,"",IF(COUNTIF(Countries!$M$1:$S$271,M8)>0,"Not a country","ERROR – NOT LISTED. Add alt spelling to ''Countries'' tab"))) | M8: Antigua and Barbuda | N8: NA | O8: =N8*365*1.28 -> #VALUE! | P8: 0.41747425 | Q8: #VALUE! | R8: =IFERROR(O8/(P8*(1-Q8)),"")
A9: =Countries!B8 -> Argentina | B9: =Countries!I8 -> Latin America | C9: =IFERROR(IFERROR(IFERROR(IFERROR(IFERROR(IFERROR(IFERROR(MATCH(Countries!$B8,$M$3:$M$1003,0),MATCH(Countries!$C8,$M$3:$M$1003,0)),MATCH(Countries!$D8,$M$3:$M$1003,0)),MATCH(Countries!$E8,$M$3:$M$1003,0)),MATCH(Countries!$F8,$M$3:$M$1003,0)),MATCH(Countries!$G8,$M$3:$M$1003,0)),MATCH(Countries!$H8,$M$3:$M$1003,0)),"X") -> 7 | D9: =IF(G$2="","",IF($C9="X","",INDEX($N$3:$CC$1003,$C9,MATCH(G$2,$N$2:$CC$2,0)))) | E9: =IF(H$2="","",IF($C9="X","",INDEX($N$3:$CC$1003,$C9,MATCH(H$2,$N$2:$CC$2,0)))) | F9: =IF(I$2="","",IF($C9="X","",INDEX($N$3:$CC$1003,$C9,MATCH(I$2,$N$2:$CC$2,0)))) | G9: =IF(A9="","",IF(G$2="","", IF(D9="",IF($K$16="Use global average",D$276,IF($K$16="Use regional average",INDEX(D$280:D$296,MATCH($B9,$B$280:$B$296,0)),IF($K$16="Leave blank","",IF($K$16="Fill with zeros", 0,IF($K$16="Use global median",D$277,"Fill out I16"))))), D9))) -> 11787.248 | H9: =IF(H$2="","", IF(E9="",IF($K$16="Use global average",E$276,IF($K$16="Use regional average",INDEX(E$280:E$296,MATCH($B9,$B$280:$B$296,0)),IF($K$16="Leave blank","",IF($K$16="Fill with zeros", 0,IF($K$16="Use global median",E$277,"Fill out I16"))))), E9)) | I9: =IF(I$2="","", IF(F9="",IF($K$16="Use global average",F$276,IF($K$16="Use regional average",INDEX(F$280:F$296,MATCH($B9,$B$280:$B$296,0)),IF($K$16="Leave blank","",IF($K$16="Fill with zeros", 0,IF($K$16="Use global median",F$277,"Fill out I16"))))), F9)) | L9: =IF(M9="","",IF(COUNTIF(Countries!$B$1:$H$271,M9)>0,"",IF(COUNTIF(Countries!$M$1:$S$271,M9)>0,"Not a country","ERROR – NOT LISTED. Add alt spelling to ''Countries'' tab"))) | M9: Argentina | N9: NA | O9: =N9*365*1.28 -> #VALUE! | P9: 0.5239751 | Q9: 0.06805 | R9: =IFERROR(O9/(P9*(1-Q9)),"")
A10: =Countries!B9 -> Armenia | B10: =Countries!I9 -> Europe | C10: =IFERROR(IFERROR(IFERROR(IFERROR(IFERROR(IFERROR(IFERROR(MATCH(Countries!$B9,$M$3:$M$1003,0),MATCH(Countries!$C9,$M$3:$M$1003,0)),MATCH(Countries!$D9,$M$3:$M$1003,0)),MATCH(Countries!$E9,$M$3:$M$1003,0)),MATCH(Countries!$F9,$M$3:$M$1003,0)),MATCH(Countries!$G9,$M$3:$M$1003,0)),MATCH(Countries!$H9,$M$3:$M$1003,0)),"X") -> 8 | D10: =IF(G$2="","",IF($C10="X","",INDEX($N$3:$CC$1003,$C10,MATCH(G$2,$N$2:$CC$2,0)))) -> 7046.4437 | E10: =IF(H$2="","",IF($C10="X","",INDEX($N$3:$CC$1003,$C10,MATCH(H$2,$N$2:$CC$2,0)))) | F10: =IF(I$2="","",IF($C10="X","",INDEX($N$3:$CC$1003,$C10,MATCH(I$2,$N$2:$CC$2,0)))) | G10: =IF(A10="","",IF(G$2="","", IF(D10="",IF($K$16="Use global average",D$276,IF($K$16="Use regional average",INDEX(D$280:D$296,MATCH($B10,$B$280:$B$296,0)),IF($K$16="Leave blank","",IF($K$16="Fill with zeros", 0,IF($K$16="Use global median",D$277,"Fill out I16"))))), D10))) -> 7046.4437 | H10: =IF(H$2="","", IF(E10="",IF($K$16="Use global average",E$276,IF($K$16="Use regional average",INDEX(E$280:E$296,MATCH($B10,$B$280:$B$296,0)),IF($K$16="Leave blank","",IF($K$16="Fill with zeros", 0,IF($K$16="Use global median",E$277,"Fill out I16"))))), E10)) | I10: =IF(I$2="","", IF(F10="",IF($K$16="Use global average",F$276,IF($K$16="Use regional average",INDEX(F$280:F$296,MATCH($B10,$B$280:$B$296,0)),IF($K$16="Leave blank","",IF($K$16="Fill with zeros", 0,IF($K$16="Use global median",F$277,"Fill out I16"))))), F10)) | K10: DATA SOURCE | L10: =IF(M10="","",IF(COUNTIF(Countries!$B$1:$H$271,M10)>0,"",IF(COUNTIF(Countries!$M$1:$S$271,M10)>0,"Not a country","ERROR – NOT LISTED. Add alt spelling to ''Countries'' tab"))) | M10: Armenia | N10: 6.7156725 | O10: =N10*365*1.28 -> 3137.5622 | P10: 0.48710114 | Q10: 0.08588 | R10: =IFERROR(O10/(P10*(1-Q10)),"") -> 7046.4437
A11: =Countries!B10 -> Australia | B11: =Countries!I10 -> Australia | C11: =IFERROR(IFERROR(IFERROR(IFERROR(IFERROR(IFERROR(IFERROR(MATCH(Countries!$B10,$M$3:$M$1003,0),MATCH(Countries!$C10,$M$3:$M$1003,0)),MATCH(Countries!$D10,$M$3:$M$1003,0)),MATCH(Countries!$E10,$M$3:$M$1003,0)),MATCH(Countries!$F10,$M$3:$M$1003,0)),MATCH(Countries!$G10,$M$3:$M$1003,0)),MATCH(Countries!$H10,$M$3:$M$1003,0)),"X") -> 10 | D11: =IF(G$2="","",IF($C11="X","",INDEX($N$3:$CC$1003,$C11,MATCH(G$2,$N$2:$CC$2,0)))) -> 46966.263 | E11: =IF(H$2="","",IF($C11="X","",INDEX($N$3:$CC$1003,$C11,MATCH(H$2,$N$2:$CC$2,0)))) | F11: =IF(I$2="","",IF($C11="X","",INDEX($N$3:$CC$1003,$C11,MATCH(I$2,$N$2:$CC$2,0)))) | G11: =IF(A11="","",IF(G$2="","", IF(D11="",IF($K$16="Use global average",D$276,IF($K$16="Use regional average",INDEX(D$280:D$296,MATCH($B11,$B$280:$B$296,0)),IF($K$16="Leave blank","",IF($K$16="Fill with zeros", 0,IF($K$16="Use global median",D$277,"Fill out I16"))))), D11))) -> 46966.263 | H11: =IF(H$2="","", IF(E11="",IF($K$16="Use global average",E$276,IF($K$16="Use regional average",INDEX(E$280:E$296,MATCH($B11,$B$280:$B$296,0)),IF($K$16="Leave blank","",IF($K$16="Fill with zeros", 0,IF($K$16="Use global median",E$277,"Fill out I16"))))), E11)) | I11: =IF(I$2="","", IF(F11="",IF($K$16="Use global average",F$276,IF($K$16="Use regional average",INDEX(F$280:F$296,MATCH($B11,$B$280:$B$296,0)),IF($K$16="Leave blank","",IF($K$16="Fill with zeros", 0,IF($K$16="Use global median",F$277,"Fill out I16"))))), F11)) | L11: =IF(M11="","",IF(COUNTIF(Countries!$B$1:$H$271,M11)>0,"",IF(COUNTIF(Countries!$M$1:$S$271,M11)>0,"Not a country","ERROR – NOT LISTED. Add alt spelling to ''Countries'' tab"))) -> Not a country | M11: Aruba | N11: NA | O11: =N11*365*1.28 -> #VALUE! | P11: 0.5050402 | Q11: #VALUE! | R11: =IFERROR(O11/(P11*(1-Q11)),"")
A12: =Countries!B11 -> Austria | B12: =Countries!I11 -> Europe | C12: =IFERROR(IFERROR(IFERROR(IFERROR(IFERROR(IFERROR(IFERROR(MATCH(Countries!$B11,$M$3:$M$1003,0),MATCH(Countries!$C11,$M$3:$M$1003,0)),MATCH(Countries!$D11,$M$3:$M$1003,0)),MATCH(Countries!$E11,$M$3:$M$1003,0)),MATCH(Countries!$F11,$M$3:$M$1003,0)),MATCH(Countries!$G11,$M$3:$M$1003,0)),MATCH(Countries!$H11,$M$3:$M$1003,0)),"X") -> 11 | D12: =IF(G$2="","",IF($C12="X","",INDEX($N$3:$CC$1003,$C12,MATCH(G$2,$N$2:$CC$2,0)))) -> 54507.986 | E12: =IF(H$2="","",IF($C12="X","",INDEX($N$3:$CC$1003,$C12,MATCH(H$2,$N$2:$CC$2,0)))) | F12: =IF(I$2="","",IF($C12="X","",INDEX($N$3:$CC$1003,$C12,MATCH(I$2,$N$2:$CC$2,0)))) | G12: =IF(A12="","",IF(G$2="","", IF(D12="",IF($K$16="Use global average",D$276,IF($K$16="Use regional average",INDEX(D$280:D$296,MATCH($B12,$B$280:$B$296,0)),IF($K$16="Leave blank","",IF($K$16="Fill with zeros", 0,IF($K$16="Use global median",D$277,"Fill out I16"))))), D12))) -> 54507.986 | H12: =IF(H$2="","", IF(E12="",IF($K$16="Use global average",E$276,IF($K$16="Use regional average",INDEX(E$280:E$296,MATCH($B12,$B$280:$B$296,0)),IF($K$16="Leave blank","",IF($K$16="Fill with zeros", 0,IF($K$16="Use global median",E$277,"Fill out I16"))))), E12)) | I12: =IF(I$2="","", IF(F12="",IF($K$16="Use global average",F$276,IF($K$16="Use regional average",INDEX(F$280:F$296,MATCH($B12,$B$280:$B$296,0)),IF($K$16="Leave blank","",IF($K$16="Fill with zeros", 0,IF($K$16="Use global median",F$277,"Fill out I16"))))), F12)) | K12: OWiD | L12: =IF(M12="","",IF(COUNTIF(Countries!$B$1:$H$271,M12)>0,"",IF(COUNTIF(Countries!$M$1:$S$271,M12)>0,"Not a country","ERROR – NOT LISTED. Add alt spelling to ''Countries'' tab"))) | M12: Australia | N12: 53.050495 | O12: =N12*365*1.28 -> 24785.191 | P12: 0.54799927 | Q12: 0.037 | R12: =IFERROR(O12/(P12*(1-Q12)),"") -> 46966.263
