Workbook

Sheet Summary
B1: Rwanda | C1: Average country in SSA | D1: AVG | E1: Notes / explanation
A2: Costs | B2: ='CEA (Rwanda)'!B116 -> 23155995 | C2: ='CEA (SSA)'!B116 -> 33688568 | D2: =AVERAGE(B2:C2) -> 28422282
A3: Benefits | B3: ='CEA (Rwanda)'!B117 -> 5.8327157e+08 | C3: ='CEA (SSA)'!B117 -> 1920423914 | D3: =AVERAGE(B3:C3) -> 1251847741 | E3: Benefits higher in SSA average case as average salary is higher than in Rwanda so an intervention that sees a % increase in salaries is more beneficial
A4: BCR | B4: ='CEA (Rwanda)'!B118 -> 25.188793 | C4: ='CEA (SSA)'!B118 -> 57.005211 | D4: =AVERAGE(B4:C4) -> 41.097002 | E4: Benefits rise more than costs for SSA average case as some costs fixed regardless of country, so a higher BCR in SSA average case
A5: $/DALY equivalent | B5: ='CEA (Rwanda)'!B125 -> 52.367299 | C5: ='CEA (SSA)'!B125 -> 46.306786 | D5: =AVERAGE(B5:C5) -> 49.337043 | E5: Difference not as extreme as BCR as the total increase in income means less to a wealthier cohort

Sheet CEA (Rwanda)
A1: 4
A2: Inputs | B2: Expected | C2: Description
A3: Costs
A4: Testing/pilot costs
A5: Duration of testing/pilot period (in years) | B5: 1 | F5: Suggested areas for improvement if more time:
A6: Fixed charity costs | B6: 125000 | C6: Best guess | F6: • Review costs, Try to get better numbers for "costs of lesson plans". For example does it make sense that at scale costs are 70% fixed costs; "Cost of lesson plans per child" could be modelled per classroom rather than per child; and "Cost of lesson plans per teacher" could look at how much training actually costs
F7: • Review the "Delay (years before any effect on growth in economy)" on "method 2".
A8: At scale costs
A9: Years delay to design program and lesson plans | B9: 1 | C9: Best guess
A10: Years to reach scale | B10: 8 | C10: Best guess
A11: Staff costs | B11: 225000 | C11: Costs roughly based on 4 staff members plus additional buffer. These costs will increase each year during scale up ie. Staff costs will be $225,000 in year 2, $550,000 in year 3, and so on until scale is reached in year 9.
A12: Cost of lesson plans per child | B12: 0.16 | C12: https://www.sciencedirect.com/science/article/pii/S0305750X18300287
A13: Cost of lesson plans per teacher | B13: 25 | C13: Assume some training and delivery costs (best guess)
A14: Years until benefit starts | B14: =AVERAGE(Calculations!$A$136:$A$138) -> 6.6666667 | C14: See calculations tab
A15: Charity years operating | B15: 30 | C15: Best guess, note this has very little effect on the results
A16: Number of years to model impact for | B16: =roundup(AVERAGE(Calculations!A128:A132),0) -> 30 | C16: See calculations tab
A17: Number of years each child needs to receive intervention to receive full benefit | B17: 8 | C17: Duration of compulsory education in SSA (World Bank)
A19: Reach
A20: Total number of primary schools in Rwanda | B20: 2961 | C20: https://www.mineduc.gov.rw/basic-education
A21: Total number of primary school aged children in school in Rwanda | B21: 2512465 | C21: Basic Education
A22: Number of children per school | B22: =B21/B20 -> 848.51908 | C22: Calculation: Total number of children / total number of schools
A23: Student-teacher ratio | B23: 58.34 | C23: Each teacher teaches 58.34 students (https://ourworldindata.org/grapher/pupil-teacher-ratio-for-primary-education-by-country?tab=table)
A24: Number of teachers per school | B24: =B22/B23 -> 14.544379 | C24: Calculation: Number of children per school / student-teacher ratio
A25: % of schools reached in pilot | B25: 0.01 | C25: Assume we work with 1% of schools during pilot (Bridge International did this in their pilot in Kenya)
A26: % of schools reached at scale | B26: 0.5 | C26: Assume we can work with 50% of schools at scale (best guess). Note: This is currently decoupled from fixed staff costs. If you decrease this, you'll presumably need to decrease staff costs too | H26: Might be lower
A27: Number of schools worked with during pilot | B27: =B20*B25 -> 29.61 | C27: Calculation: Number of schools * % of schools worked with
A28: Number of schools worked with in year 2 | B28: =$B$27+(($B$35-$B$27)/$B$10) -> 210.97125
A29: Number of schools worked with in year 3 | B29: =B28+(($B$35-$B$27)/$B$10) -> 392.3325
A30: Number of schools worked with in year 4 | B30: =B29+(($B$35-$B$27)/$B$10) -> 573.69375
A31: Number of schools worked with in year 5 | B31: =B30+(($B$35-$B$27)/$B$10) -> 755.055
A32: Number of schools worked with in year 6 | B32: =B31+(($B$35-$B$27)/$B$10) -> 936.41625
A33: Number of schools worked with in year 7 | B33: =B32+(($B$35-$B$27)/$B$10) -> 1117.7775
A34: Number of schools worked with in year 8 | B34: =B33+(($B$35-$B$27)/$B$10) -> 1299.1388
A35: Number of schools worked with at scale | B35: =B20*B26 -> 1480.5 | C35: Calculation: Number of schools * % of schools worked with
A36: Number of children reached during pilot | B36: =B27*B22 -> 25124.65 | C36: Calculation: Number of children per school * number of schools worked with during pilot
A37: Number of children worked with in year 2 | B37: =B36+(($B$44-$B$36)/$B$10) -> 179013.13
A38: Number of children worked with in year 3 | B38: =B37+(($B$44-$B$36)/$B$10) -> 332901.61
A39: Number of children worked with in year 4 | B39: =B38+(($B$44-$B$36)/$B$10) -> 486790.09
A40: Number of children worked with in year 5 | B40: =B39+(($B$44-$B$36)/$B$10) -> 640678.57
A41: Number of children worked with in year 6 | B41: =B40+(($B$44-$B$36)/$B$10) -> 794567.06
...

Sheet CEA (SSA)
A1: A new charity introducing lesson plans into schools in an average country in SSA. The charity will do a pilot in its first year in private schools, then take the results of this pilot to governments and ask to pilot it and scale it up in government schools.
A2: Inputs | B2: Expected | C2: Description
A3: Costs
A4: Testing/pilot costs
A5: Duration of testing/pilot period (in years) | B5: 1 | F5: Suggested areas for improvement if more time:
A6: Fixed charity costs | B6: 125000 | C6: Best guess | F6: • Review costs, Try to get better numbers for "costs of lesson plans". For example does it make sense that at scale costs are 70% fixed costs; "Cost of lesson plans per child" could be modelled per classroom rather than per child; and "Cost of lesson plans per teacher" could look at how much training actually costs
F7: • Review the "Delay (years before any effect on growth in economy)" on "method 2".
A8: At scale costs
A9: Years delay to design program and lesson plans | B9: 1 | C9: Best guess
A10: Years to reach scale | B10: 8 | C10: Best guess
A11: Staff costs | B11: 225000 | C11: Costs roughly based on 4 staff members plus additional buffer. These costs will increase each year during scale up ie. Staff costs will be $225,000 in year 2, $550,000 in year 3, and so on until scale is reached in year 9.
A12: Cost of lesson plans per child | B12: 0.16 | C12: https://www.sciencedirect.com/science/article/pii/S0305750X18300287
A13: Cost of lesson plans per teacher | B13: 25 | C13: Assume some training and delivery costs (best guess)
A14: Years until benefit starts | B14: =AVERAGE(Calculations!$A$136:$A$138) -> 6.6666667 | C14: See calculations tab
A15: Charity years operating | B15: 30 | C15: Best guess, note this has very little effect on the results
A16: Number of years to model impact for | B16: =roundup(AVERAGE(Calculations!A128:A132),0) -> 30 | C16: See calculations tab
A17: Number of years each child needs to receive intervention to receive full benefit | B17: 8 | C17: Duration of compulsory education in SSA (World Bank)
A19: Reach
A20: Total number of schools in average country in SSA | B20: 12225
A21: Number of children out of school in SSA | B21: 265188
A22: % of children out of school in SSA | B22: 0.06
A23: Total number of primary school aged children in average country in SSA | B23: =B21/B22 -> 4419800 | C23: I couldn't find information on the total number of primary school aged children in the average country in SSA, so instead I used the number of children out of school and as we know that 6% of primary school aged children are out of school, we can calculate the total number of primary school aged children Calculation: Number of children out of school / % of children out of school
A24: Number of children per school | B24: =B23/B20 -> 361.53783 | C24: Calculation: Total number of children / total number of schools
A25: Student-teacher ratio | B25: 41.67 | C25: Each teacher teaches 41.67 students (https://ourworldindata.org/grapher/pupil-teacher-ratio-for-primary-education-by-country?tab=table)
A26: Number of teachers per school | B26: =B24/B25 -> 8.6762139 | C26: Calculation: Number of children per school / student-teacher ratio
A27: % of schools reached in pilot | B27: 0.01 | C27: Assume we work with 1% of schools during pilot (Bridge International did this in their pilot in Kenya)
A28: % of schools reached at scale | B28: 0.5 | C28: Assume we can work with 50% of schools at scale (best guess) | G28: Might be lower
A29: Number of schools worked with during pilot | B29: =B20*B27 -> 122.25 | C29: Calculation: Number of schools * % of schools worked with
A30: Number of schools worked with in year 2 | B30: =$B$29+(($B$37-$B$29)/$B$10) -> 871.03125
A31: Number of schools worked with in year 3 | B31: =B30+(($B$37-$B$29)/$B$10) -> 1619.8125
A32: Number of schools worked with in year 4 | B32: =B31+(($B$37-$B$29)/$B$10) -> 2368.5938
A33: Number of schools worked with in year 5 | B33: =B32+(($B$37-$B$29)/$B$10) -> 3117.375
A34: Number of schools worked with in year 6 | B34: =B33+(($B$37-$B$29)/$B$10) -> 3866.1562
A35: Number of schools worked with in year 7 | B35: =B34+(($B$37-$B$29)/$B$10) -> 4614.9375
A36: Number of schools worked with in year 8 | B36: =B35+(($B$37-$B$29)/$B$10) -> 5363.7188
A37: Number of schools worked with at scale | B37: =B20*B28 -> 6112.5 | C37: Calculation: Number of schools * % of schools worked with
A38: Number of children reached during pilot | B38: =B29*B24 -> 44198 | C38: Calculation: Number of children per school * number of schools worked with during pilot
A39: Number of children worked with in year 2 | B39: =B38+(($B$46-$B$38)/$B$10) -> 314910.75
A40: Number of children worked with in year 3 | B40: =B39+(($B$46-$B$38)/$B$10) -> 585623.5
A41: Number of children worked with in year 4 | B41: =B40+(($B$46-$B$38)/$B$10) -> 856336.25
...

Sheet Calculations
A1: METHOD 1 – BASED ON INCOME EFFECTS
A2: Returns to education (Additional years of schooling -> Income increase)
A3: Findings | F3: Source | G3: Notes
A4: 1 | B4: additional year of schooling | C4: = | D4: 0.1 | E4: income increase | F4: Woodleigh Impact (informed by Psacharopoulos and Patrinos & World Bank)
A5: 1 | B5: additional year of schooling | C5: = | D5: 0.19047619 | E5: income increase | F5: EA Quebec (using Duflo, 2017)
A6: 1 | B6: additional year of schooling | C6: = | D6: 0.088 | E6: income increase (World average) | F6: Psacharopoulos and Patrinos, 2018
A7: 1 | B7: additional year of schooling | C7: = | D7: 0.105 | E7: income increase (in SSA) | F7: Psacharopoulos and Patrinos, 2018
A8: 1 | B8: additional year of schooling (Primary school) | C8: = | D8: 0.254 | E8: income increase | F8: Psacharopoulos and Patrinos, 2018
A9: 1 | B9: additional year of schooling | C9: = | D9: 0.097 | E9: income increase (World average) | F9: World Bank, 2014
A10: 1 | B10: additional year of schooling | C10: = | D10: 0.101 | E10: income increase (World average) | F10: World Bank, 2014
A11: 1 | B11: additional year of schooling | C11: = | D11: 0.124 | E11: income increase (in SSA) | F11: World Bank, 2014
A12: 1 | B12: additional year of schooling (Primary school) | C12: = | D12: 0.106 | E12: income increase | F12: World Bank, 2014
A13: 1 | B13: additional year of schooling (Primary school) | C13: = | D13: 0.115 | E13: income increase | F13: World Bank, 2014
A14: 1 | B14: additional year of schooling (Primary school) | C14: = | D14: 0.144 | E14: income increase (in SSA) | F14: World Bank, 2014
A15: 1 | B15: additional year of schooling | C15: = | D15: 0 | E15: income increase | F15: Filmer and Schady, 2014
C16: AVERAGE | D16: =AVERAGE(D4:D15) -> 0.11870635
A18: Returns to education (SD increase in test scores = Additional years of schooling)
A19: Findings | F19: Source | G19: Notes
A20: 1 | B20: SD increase in test scores | C20: = | D20: =AVERAGE(1.666666667,6.9) -> 4.2833333 | E20: additional years of schooling | F20: Woodleigh Impact (using Sabbates et al., 2018) | G20: 1.666666667 to 6.9 additional years of schooling
A21: 1 | B21: SD increase in test scores | C21: = | D21: =AVERAGE(8.4,10.5) -> 9.45 | E21: additional years of schooling | F21: EA Quebec (using Duflo, 2017) | G21: 8.4 to 10.5 additional years of schooling
A22: 1 | B22: SD increase in test scores | C22: = | D22: =AVERAGE(1,4.5) -> 2.75 | E22: additional years of schooling | F22: EA Quebec (using World Bank, 2014 and Hanushek et al., 2016) | G22: 1 to 4.5 additional years of schooling
C23: AVERAGE | D23: =AVERAGE(D20:D22) -> 5.4944444
A25: Returns to education (SD increase in test scores -> Income increase)
A26: Findings | F26: Source | G26: Notes
A27: 1 | B27: SD increase in test scores | C27: = | D27: =AVERAGE(0.12,0.25) -> 0.185 | E27: income increase | F27: Hanushek et al., 2013 | G27: 12% to 25%
A28: 1 | B28: SD increase in test scores | C28: = | D28: =AVERAGE(0.1,0.45) -> 0.275 | E28: income increase | F28: Hanushek et al., 2016 | G28: 10% to 45%
A29: 1 | B29: SD increase in test scores | C29: = | D29: =AVERAGE(0.01,0.25) -> 0.13 | E29: income increase | F29: Founders Pledge | G29: 1 to 25%
A30: 1 | B30: SD increase in test scores | C30: = | D30: 0.4 | E30: income increase | F30: EA Quebec (using Bettinger et al., 2014 and 2017 [Unpublished; Cited by FP and GW in their reports])
A31: 1 | B31: SD increase in test scores | C31: = | D31: =$D$20*D4 -> 0.42833333 | E31: income increase | F31: Calculation | G31: $D$19*D4
A32: 1 | B32: SD increase in test scores | C32: = | D32: =$D$20*D5 -> 0.81587302 | E32: income increase | F32: Calculation | G32: $D$19*D5
A33: 1 | B33: SD increase in test scores | C33: = | D33: =$D$20*D6 -> 0.37693333 | E33: income increase | F33: Calculation | G33: $D$19*D6
A34: 1 | B34: SD increase in test scores | C34: = | D34: =$D$20*D7 -> 0.44975 | E34: income increase | F34: Calculation | G34: $D$19*D7
A35: 1 | B35: SD increase in test scores | C35: = | D35: =$D$20*D8 -> 1.0879667 | E35: income increase | F35: Calculation | G35: $D$19*D8
A36: 1 | B36: SD increase in test scores | C36: = | D36: =$D$20*D9 -> 0.41548333 | E36: income increase | F36: Calculation | G36: $D$19*D9
A37: 1 | B37: SD increase in test scores | C37: = | D37: =$D$20*D10 -> 0.43261667 | E37: income increase | F37: Calculation | G37: $D$19*D10
A38: 1 | B38: SD increase in test scores | C38: = | D38: =$D$20*D11 -> 0.53113333 | E38: income increase | F38: Calculation | G38: $D$19*D11
A39: 1 | B39: SD increase in test scores | C39: = | D39: =$D$20*D12 -> 0.45403333 | E39: income increase | F39: Calculation | G39: $D$19*D12
A40: 1 | B40: SD increase in test scores | C40: = | D40: =$D$20*D13 -> 0.49258333 | E40: income increase | F40: Calculation | G40: $D$19*D13
A41: 1 | B41: SD increase in test scores | C41: = | D41: =$D$20*D14 -> 0.6168 | E41: income increase | F41: Calculation | G41: $D$19*D14
A42: 1 | B42: SD increase in test scores | C42: = | D42: =$D$20*D15 -> 0 | E42: income increase | F42: Calculation | G42: $D$19*D15
...
